Workbook

Sheet Data Angt
A1: LAPORAN ANGGOTA
F3: 2025
A4: No. Agt | B4: Nama | C4: TP | D4: JK | E4: Tgl Lahir | F4: USIA | G4: Pekerjaan | H4: PROFESI | I4: Bidang Usaha | J4: Nama Instansi
A5: 14053.001.1000.006 | B5: A1 | C5: PBL | D5: L | E5: 17-08-1949 | F5: 76 | G5: Pensiunan | H5: Pensiunan
A6: 14053.001.1000.008 | B6: A2 | C6: PBL | D6: L | E6: 11-07-1965 | F6: 60 | G6: Guru | H6: Tenaga Pengajar | I6: PENDIDIKAN | J6: SDK MATER DEI
A7: 14053.001.1000.009 | B7: A3 | C7: PBL | D7: L | E7: 23-12-1968 | F7: 57 | G7: Guru | H7: Tenaga Pengajar | I7: PENDIDIKAN | J7: SDK MATER DEI
A8: 14053.001.1000.012 | B8: A4 | C8: PBL | D8: P | E8: 07-10-1969 | F8: 56 | G8: Karyawan Swasta | H8: Karyawan | I8: PENDIDIKAN | J8: STELLA MARIS SURABAYA
A9: 14053.001.1000.031 | B9: A5 | C9: PBL | D9: P | E9: 10-12-1967 | F9: 58 | G9: Pembantu Rumah Tangga | H9: Lain-Lain | J9: ASRAMA MATER DEI
A10: 14053.001.1000.032 | B10: A6 | C10: PBL | D10: P | E10: 18-06-1967 | F10: 58 | G10: Mengurus Rumah Tangga | H10: Mengurus Rumah Tangga | I10: RUMAH TANGGA | J10: IBU RUMAH TANGGA
A11: 14053.001.1000.033 | B11: A7 | C11: PBL | D11: P | E11: 01-07-1941 | F11: 84 | G11: Mengurus Rumah Tangga | H11: Mengurus Rumah Tangga
A12: 14053.001.1000.037 | B12: A8 | C12: PBL | D12: L | E12: 16-08-1966 | F12: 59 | G12: Pensiunan | H12: Pensiunan | I12: SDK MATER DEI | J12: SDK MATER DEI
A13: 14053.001.1000.039 | B13: A9 | C13: PBL | D13: P | E13: 10-11-1965 | F13: 60 | G13: Pensiunan | H13: Pensiunan | I13: PENDIDIKAN | J13: SDK MATER DEI
A14: 14053.001.1000.040 | B14: A10 | C14: PBL | D14: P | E14: 13-09-1960 | F14: 65 | G14: Pensiunan | H14: Pensiunan | J14: SDK MATER DEI
A15: 14053.001.1000.041 | B15: A11 | C15: PBL | D15: L | E15: 29-05-1972 | F15: 53 | G15: Guru | H15: Tenaga Pengajar | I15: PENDIDIKAN | J15: SDK MATER DEI
A16: 14053.001.1000.042 | B16: A12 | C16: PBL | D16: P | E16: 10-11-1964 | F16: 61 | G16: Wiraswasta | H16: Wiraswasta | I16: TOKO SEPATU | J16: TOKO GAYAKU
A17: 14053.001.1000.045 | B17: A13 | C17: PBL | D17: P | E17: 21-11-1963 | F17: 62 | G17: Wiraswasta | H17: Wiraswasta | I17: PERDAGANGAN | J17: TOKO KELONTONG
A18: 14053.001.1000.047 | B18: A14 | C18: PBL | D18: P | E18: 21-12-1956 | F18: 69 | G18: Pensiunan | H18: Pensiunan | I18: GURU | J18: SMPK MATER DEI
A19: 14053.001.1000.049 | B19: A15 | C19: PBL | D19: P | E19: 18-08-1970 | F19: 55 | G19: Guru | H19: Tenaga Pengajar | I19: PENDIDIKAN | J19: SMPK MATER DEI
A20: 14053.001.1000.051 | B20: A16 | C20: PBL | D20: P | E20: 25-10-1970 | F20: 55 | G20: Guru | H20: Tenaga Pengajar | I20: PENDIDIKAN | J20: SDK MATER DEI
A21: 14053.001.1000.052 | B21: A17 | C21: PBL | D21: L | E21: 28-07-1965 | F21: 60 | G21: Guru | H21: Tenaga Pengajar | I21: PENDIDIKAN | J21: SMPK MATER DEI
A22: 14053.001.1000.053 | B22: A18 | C22: PBL | D22: P | E22: 09-09-1948 | F22: 77 | G22: Pensiunan | H22: Pensiunan | J22: SMPK MATER DEI
A23: 14053.001.1000.054 | B23: A19 | C23: PBL | D23: P | E23: 17-03-1962 | F23: 63 | G23: Pensiunan | H23: Pensiunan | J23: SMPK MATER DEI
A24: 14053.001.1000.056 | B24: A20 | C24: PBL | D24: L | E24: 10-08-1952 | F24: 73 | G24: Pensiunan | H24: Pensiunan | I24: PENDIDIKAN | J24: SMAK MATER DEI
A25: 14053.001.1000.058 | B25: A21 | C25: PBL | D25: P | E25: 01-07-1963 | F25: 62 | G25: Pembantu Rumah Tangga | H25: Lain-Lain | J25: ASRAMA ST. JAN
A26: 14053.001.1000.061 | B26: A22 | C26: PBL | D26: L | E26: 24-07-1960 | F26: 65 | G26: Wiraswasta | H26: Wiraswasta | I26: PEMILIK TOKO PERACANGAN | J26: TOKO PERACANGAN
A27: 14053.001.1000.069 | B27: A23 | C27: PBL | D27: P | E27: 31-10-1972 | F27: 53 | G27: Guru | H27: Tenaga Pengajar | I27: PENDIDIKAN | J27: TK MATER DEI
A28: 14053.001.1000.070 | B28: A24 | C28: PBL | D28: P | E28: 20-11-1966 | F28: 59 | G28: Guru | H28: Tenaga Pengajar | I28: PENDIDIKAN | J28: TKK MATER DEI PROBOLINGGO
A29: 14053.001.1000.071 | B29: A25 | C29: PBL | D29: L | E29: 11-09-1959 | F29: 66 | G29: Pensiunan | H29: Pensiunan | J29: SMUK MATER DEI
A30: 14053.001.1000.082 | B30: A26 | C30: PBL | D30: P | E30: 14-12-1974 | F30: 51 | G30: Perawat | H30: Tenaga Medis | I30: KESEHATAN GIGI | J30: PERAWAT GIGI
A31: 14053.001.1000.084 | B31: A27 | C31: PBL | D31: P | E31: 10-12-1964 | F31: 61 | G31: Pensiunan | H31: Pensiunan | I31: WIRAUSAHA | J31: SMPK MATER DEI
A32: 14053.001.1000.087 | B32: A28 | C32: PBL | D32: L | E32: 14-11-1947 | F32: 78 | G32: Pensiunan | H32: Pensiunan
A33: 14053.001.1000.090 | B33: A29 | C33: PBL | D33: L | E33: 10-05-1965 | F33: 60 | G33: Pensiunan | H33: Pensiunan | J33: SMPK MATER DEI
A34: 14053.001.1000.097 | B34: A30 | C34: PBL | D34: P | E34: 30-11-1956 | F34: 69 | G34: Pensiunan | H34: Pensiunan | J34: SMPK MATER DEI
A35: 14053.001.1000.098 | B35: A31 | C35: PBL | D35: P | E35: 13-03-1966 | F35: 59 | G35: Pensiunan | H35: Tenaga Pengajar | I35: PENDIDIKAN | J35: TK MATER DEI
A36: 14053.001.1000.101 | B36: A32 | C36: PBL | D36: P | E36: 11-05-1967 | F36: 58 | G36: Guru | H36: Tenaga Pengajar | I36: PENDIDIKAN | J36: TK MATER DEI
A37: 14053.001.1000.106 | B37: A33 | C37: PBL | D37: P | E37: 11-08-1971 | F37: 54 | G37: Guru | H37: Tenaga Pengajar | I37: PENDIDIKAN | J37: SD MATER DEI
A38: 14053.001.1000.107 | B38: A34 | C38: PBL | D38: P | E38: 12-03-1963 | F38: 62 | G38: Karyawan Swasta | H38: Karyawan | I38: KESEHATAN | J38: APOTIK SUMBER BARU
A39: 14053.001.1000.110 | B39: A35 | C39: PBL | D39: L | E39: 03-10-1972 | F39: 53 | G39: Karyawan Swasta | H39: Karyawan | I39: KEBERSIHAN | J39: TK MATER DEI
A40: 14053.001.1000.116 | B40: A36 | C40: PBL | D40: P | E40: 24-10-1959 | F40: 66 | G40: Pensiunan | H40: Pensiunan | J40: SDK MATER DEI
A41: 14053.001.1000.117 | B41: A37 | C41: PBL | D41: P | E41: 14-10-1960 | F41: 65 | G41: Pensiunan | H41: Pensiunan | I41: PENDIDIKAN | J41: SMAK MATER DEI
...

Sheet Rekap
B2: 1 | C2: KLASIFIKASI USIA ANGGOTA | I2: KLASIFIKASI USIA PEMINJAM | M2: KLASIFIKASI TUJUAN PINJAMAN | T2: KLASIFIKASI USIA PENABUNG
C3: Usia | D3: Jml Agt | E3: % | I3: Usia | J3: Jml Agt | K3: % | M3: Usia | N3: Jml Agt | O3: % | T3: Usia | U3: SSKA | V3: SJTA | W3: SPJ | X3: SMP
C4: < 17 | D4: =COUNTIF('Data Angt'!$F$5:$F$5710,"<17") -> 9 | E4: =D4/$D$8 -> 0.0015889831 | I4: <= 23 | J4: =COUNTIF(Pinjaman!$V$6:$V$1373,"<24") -> 30 | K4: =J4/$J$7 -> 0.021945867 | M4: KONSUMTIF | N4: =COUNTIF(Pinjaman!$W$6:$W$1373,M4) -> 312 | O4: =N4/$N$10 -> 0.22807018 | T4: <= 23 | U4: =COUNTIF(SSKA!$P$7:$P$466,"<24") -> 0 | V4: =COUNTIF(SJTA!$R$6:$R$331,"<24") -> 27 | W4: =COUNTIF(SPJ!$O$5:$O$136,"<24") -> 9 | X4: =COUNTIF(SMP!$O$6:$O$15,"<24") -> 0
C5: 17 - 23 | D5: =COUNTIF('Data Angt'!$F$5:$F$5710,"<24")-COUNTIF('Data Angt'!$F$5:$F$5710,"<17") -> 322 | E5: =D5/$D$8 -> 0.056850282 | I5: 24 - 60 | J5: =COUNTIF(Pinjaman!$V$6:$V$1373,"<=60")-COUNTIF(Pinjaman!$V$6:$V$1373,"<24") -> 1188 | K5: =J5/$J$7 -> 0.86905633 | M5: KESEJAHTERAAN | N5: =COUNTIF(Pinjaman!$W$6:$W$1373,M5) -> 234 | O5: =N5/$N$10 -> 0.17105263 | T5: 24 - 60 | U5: =COUNTIF(SSKA!$P$7:$P$466,"<=60")-COUNTIF(SSKA!$P$7:$P$466,"<24") -> 0 | V5: =COUNTIF(SJTA!$R$6:$R$331,"<=60")-COUNTIF(SJTA!$R$6:$R$331,"<24") -> 215 | W5: =COUNTIF(SPJ!$O$5:$O$136,"<=60")-COUNTIF(SPJ!$O$5:$O$136,"<24") -> 121 | X5: =COUNTIF(SMP!$O$6:$O$15,"<=60")-COUNTIF(SMP!$O$6:$O$15,"<24") -> 8
C6: 24 - 60 | D6: =COUNTIF('Data Angt'!$F$5:$F$5710,"<=60")-COUNTIF('Data Angt'!$F$5:$F$5710,"<24") -> 4469 | E6: =D6/$D$8 -> 0.78901836 | I6: > 60 | J6: =COUNTIF(Pinjaman!$V$6:$V$1373,">60") -> 149 | K6: =J6/$J$7 -> 0.10899781 | M6: PENDIDIKAN | N6: =COUNTIF(Pinjaman!$W$6:$W$1373,M6) -> 209 | O6: =N6/$N$10 -> 0.15277778 | T6: > 60 | U6: =COUNTIF(SSKA!$P$7:$P$466,">60") -> 0 | V6: =COUNTIF(SJTA!$R$6:$R$331,">60") -> 74 | W6: =COUNTIF(SPJ!$O$5:$O$136,">60") -> 2 | X6: =COUNTIF(SMP!$O$6:$O$15,">60") -> 2
C7: > 60 | D7: =COUNTIF('Data Angt'!$F$5:$F$5710,">60") -> 864 | E7: =D7/$D$8 -> 0.15254237 | I7: JML | J7: =SUM(J4:J6) -> 1367 | K7: =J7/$J$7 -> 1 | M7: PRODUKTIF | N7: =COUNTIF(Pinjaman!$W$6:$W$1373,M7) -> 529 | O7: =N7/$N$10 -> 0.38669591 | T7: JML | U7: =SUM(U4:U6) -> 0 | V7: =SUM(V4:V6) -> 316 | W7: =SUM(W4:W6) -> 132 | X7: =SUM(X4:X6) -> 10
C8: JML | D8: =SUM(D4:D7) -> 5664 | E8: =D8/$D$8 -> 1 | M8: KESEHATAN | N8: =COUNTIF(Pinjaman!$W$6:$W$1373,M8) -> 16 | O8: =N8/$N$10 -> 0.011695906
D9: =D8-COUNTIF('Data Angt'!B5:B5710,"<>0") -> -42 | M9: DATA KOSONG | N9: =COUNTIF(Pinjaman!$W$6:$W$1373,0) -> 68 | O9: =N9/$N$10 -> 0.049707602
M10: JUMLAH | N10: =SUM(N4:N9) -> 1368 | O10: =N10/$N$10 -> 1 | T10: Profesi | U10: SSKA | V10: SJTA | W10: SPJ | X10: SMP
B11: 2 | C11: KLASIFIKASI PROFESI ANGGOTA | T11: Karyawan | U11: =COUNTIF(SSKA!$Q$7:$Q$466,Rekap!$T11) -> 0 | V11: =COUNTIF(SJTA!$S$6:$S$331,T11) -> 71 | W11: =COUNTIF(SPJ!$P$5:$P$136,T11) -> 33 | X11: =COUNTIF(SMP!$P$6:$P$15,T11) -> 4
C12: Profesi | D12: Jml Agt | E12: % | T12: Wiraswasta | U12: =COUNTIF(SSKA!$Q$7:$Q$466,Rekap!$T12) -> 0 | V12: =COUNTIF(SJTA!$S$6:$S$331,T12) -> 42 | W12: =COUNTIF(SPJ!$P$5:$P$136,T12) -> 28 | X12: =COUNTIF(SMP!$P$6:$P$15,T12) -> 2
C13: Karyawan | D13: =COUNTIF('Data Angt'!$H$5:$H$5710,C13) -> 1583 | E13: =D13/$D$27 -> 0.29533582 | I13: KLASIFIKASI TUJUAN PINJAMAN BERDASAR USIA PEMINJAM | T13: Pelajar/Mahasiswa | U13: =COUNTIF(SSKA!$Q$7:$Q$466,Rekap!$T13) -> 0 | V13: =COUNTIF(SJTA!$S$6:$S$331,T13) -> 25 | W13: =COUNTIF(SPJ!$P$5:$P$136,T13) -> 12 | X13: =COUNTIF(SMP!$P$6:$P$15,T13) -> 0
C14: Wiraswasta | D14: =COUNTIF('Data Angt'!$H$5:$H$5710,C14) -> 1339 | E14: =D14/$D$27 -> 0.24981343 | I14: USIA | J14: KONSUMTIF | K14: KESEJAHTERAAN | L14: PENDIDIKAN | M14: PRODUKTIF | N14: KESEHATAN | O14: DATA KOSONG | P14: JML | T14: Mengurus Rumah Tangga | U14: =COUNTIF(SSKA!$Q$7:$Q$466,Rekap!$T14) -> 0 | V14: =COUNTIF(SJTA!$S$6:$S$331,T14) -> 39 | W14: =COUNTIF(SPJ!$P$5:$P$136,T14) -> 22 | X14: =COUNTIF(SMP!$P$6:$P$15,T14) -> 0
C15: Pelajar/Mahasiswa | D15: =COUNTIF('Data Angt'!$H$5:$H$5710,C15) -> 229 | E15: =D15/$D$27 -> 0.042723881 | I15: < 17 | J15: =COUNTIFS(Pinjaman!$W$6:$W$1373,J$14,Pinjaman!$V$6:$V$1373,"<17") -> 0 | K15: =COUNTIFS(Pinjaman!$W$6:$W$1373,K$14,Pinjaman!$V$6:$V$1373,"<17") -> 0 | L15: =COUNTIFS(Pinjaman!$W$6:$W$1373,L$14,Pinjaman!$V$6:$V$1373,"<17") -> 0 | M15: =COUNTIFS(Pinjaman!$W$6:$W$1373,M$14,Pinjaman!$V$6:$V$1373,"<17") -> 0 | N15: =COUNTIFS(Pinjaman!$W$6:$W$1373,N$14,Pinjaman!$V$6:$V$1373,"<17") -> 0 | O15: =COUNTIFS(Pinjaman!W6:W1373,0,Pinjaman!V6:V1373,"<17") -> 0 | P15: =SUM(J15:O15) -> 0 | T15: Tenaga Pengajar | U15: =COUNTIF(SSKA!$Q$7:$Q$466,Rekap!$T15) -> 0 | V15: =COUNTIF(SJTA!$S$6:$S$331,T15) -> 37 | W15: =COUNTIF(SPJ!$P$5:$P$136,T15) -> 14 | X15: =COUNTIF(SMP!$P$6:$P$15,T15) -> 1
C16: Mengurus Rumah Tangga | D16: =COUNTIF('Data Angt'!$H$5:$H$5710,C16) -> 839 | E16: =D16/$D$27 -> 0.15652985 | I16: 17 - 23 | J16: =COUNTIFS(Pinjaman!$W$6:$W$1373,J$14,Pinjaman!$V$6:$V$1373,"<24")-COUNTIFS(Pinjaman!$W$6:$W$1373,J$14,Pinjaman!$V$6:$V$1373,"<17") -> 14 | K16: =COUNTIFS(Pinjaman!$W$6:$W$1373,K$14,Pinjaman!$V$6:$V$1373,"<24")-COUNTIFS(Pinjaman!$W$6:$W$1373,K$14,Pinjaman!$V$6:$V$1373,"<17") -> 6 | L16: =COUNTIFS(Pinjaman!$W$6:$W$1373,L$14,Pinjaman!$V$6:$V$1373,"<24")-COUNTIFS(Pinjaman!$W$6:$W$1373,L$14,Pinjaman!$V$6:$V$1373,"<17") -> 3 | M16: =COUNTIFS(Pinjaman!$W$6:$W$1373,M$14,Pinjaman!$V$6:$V$1373,"<24")-COUNTIFS(Pinjaman!$W$6:$W$1373,M$14,Pinjaman!$V$6:$V$1373,"<17") -> 7 | N16: =COUNTIFS(Pinjaman!$W$6:$W$1373,N$14,Pinjaman!$V$6:$V$1373,"<24")-COUNTIFS(Pinjaman!$W$6:$W$1373,N$14,Pinjaman!$V$6:$V$1373,"<17") -> 0 | O16: =COUNTIFS(Pinjaman!W6:W1373,0,Pinjaman!V6:V1373,"<24")-COUNTIFS(Pinjaman!W6:W1373,0,Pinjaman!V6:V1373,"<17") -> 0 | P16: =SUM(J16:O16) -> 30 | T16: Lain-Lain | U16: =COUNTIF(SSKA!$Q$7:$Q$466,Rekap!$T16) -> 0 | V16: =COUNTIF(SJTA!$S$6:$S$331,T16) -> 17 | W16: =COUNTIF(SPJ!$P$5:$P$136,T16) -> 4 | X16: =COUNTIF(SMP!$P$6:$P$15,T16) -> 0
C17: Tenaga Pengajar | D17: =COUNTIF('Data Angt'!$H$5:$H$5710,C17) -> 448 | E17: =D17/$D$27 -> 0.08358209 | I17: 24 - 60 | J17: =COUNTIFS(Pinjaman!$W$6:$W$1373,J$14,Pinjaman!$V$6:$V$1373,"<=60")-COUNTIFS(Pinjaman!$W$6:$W$1373,J$14,Pinjaman!$V$6:$V$1373,"<24") -> 260 | K17: =COUNTIFS(Pinjaman!$W$6:$W$1373,K$14,Pinjaman!$V$6:$V$1373,"<=60")-COUNTIFS(Pinjaman!$W$6:$W$1373,K$14,Pinjaman!$V$6:$V$1373,"<24") -> 198 | L17: =COUNTIFS(Pinjaman!$W$6:$W$1373,L$14,Pinjaman!$V$6:$V$1373,"<=60")-COUNTIFS(Pinjaman!$W$6:$W$1373,L$14,Pinjaman!$V$6:$V$1373,"<24") -> 196 | M17: =COUNTIFS(Pinjaman!$W$6:$W$1373,M$14,Pinjaman!$V$6:$V$1373,"<=60")-COUNTIFS(Pinjaman!$W$6:$W$1373,M$14,Pinjaman!$V$6:$V$1373,"<24") -> 464 | N17: =COUNTIFS(Pinjaman!$W$6:$W$1373,N$14,Pinjaman!$V$6:$V$1373,"<=60")-COUNTIFS(Pinjaman!$W$6:$W$1373,N$14,Pinjaman!$V$6:$V$1373,"<24") -> 13 | O17: =COUNTIFS(Pinjaman!W6:W1373,0,Pinjaman!V6:V1373,"<=60")-COUNTIFS(Pinjaman!W6:W1373,0,Pinjaman!V6:V1373,"<24") -> 57 | P17: =SUM(J17:O17) -> 1188 | T17: Aparatur Negara | U17: =COUNTIF(SSKA!$Q$7:$Q$466,Rekap!$T17) -> 0 | V17: =COUNTIF(SJTA!$S$6:$S$331,T17) -> 0 | W17: =COUNTIF(SPJ!$P$5:$P$136,T17) -> 0 | X17: =COUNTIF(SMP!$P$6:$P$15,T17) -> 0
C18: Tenaga Medis | I18: > 60 | J18: =COUNTIFS(Pinjaman!$W$6:$W$1373,J$14,Pinjaman!$V$6:$V$1373,">60") -> 38 | K18: =COUNTIFS(Pinjaman!$W$6:$W$1373,K$14,Pinjaman!$V$6:$V$1373,">60") -> 30 | L18: =COUNTIFS(Pinjaman!$W$6:$W$1373,L$14,Pinjaman!$V$6:$V$1373,">60") -> 10 | M18: =COUNTIFS(Pinjaman!$W$6:$W$1373,M$14,Pinjaman!$V$6:$V$1373,">60") -> 57 | N18: =COUNTIFS(Pinjaman!$W$6:$W$1373,N$14,Pinjaman!$V$6:$V$1373,">60") -> 3 | O18: =COUNTIFS(Pinjaman!W6:W1373,0,Pinjaman!V6:V1373,">60") -> 11 | P18: =SUM(J18:O18) -> 149 | T18: Pensiunan | U18: =COUNTIF(SSKA!$Q$7:$Q$466,Rekap!$T18) -> 0 | V18: =COUNTIF(SJTA!$S$6:$S$331,T18) -> 32 | W18: =COUNTIF(SPJ!$P$5:$P$136,T18) -> 4 | X18: =COUNTIF(SMP!$P$6:$P$15,T18) -> 1
C19: Lain-Lain | D19: =COUNTIF('Data Angt'!$H$5:$H$5710,C19) -> 245 | E19: =D19/$D$27 -> 0.045708955 | I19: JML | J19: =SUM(J15:J18) -> 312 | K19: =SUM(K15:K18) -> 234 | L19: =SUM(L15:L18) -> 209 | M19: =SUM(M15:M18) -> 528 | N19: =SUM(N15:N18) -> 16 | O19: =SUM(O15:O18) -> 68 | P19: =SUM(J19:O19) -> 1367 | T19: Pemuka Agama | U19: =COUNTIF(SSKA!$Q$7:$Q$466,Rekap!$T19) -> 0 | V19: =COUNTIF(SJTA!$S$6:$S$331,T19) -> 13 | W19: =COUNTIF(SPJ!$P$5:$P$136,T19) -> 0 | X19: =COUNTIF(SMP!$P$6:$P$15,T19) -> 0
C20: Aparatur Negara | D20: =COUNTIF('Data Angt'!$H$5:$H$5710,C20) -> 0 | E20: =D20/$D$27 -> 0 | T20: Petani/Pekebun/Nelayan/Peternak | U20: =COUNTIF(SSKA!$Q$7:$Q$466,Rekap!$T20) -> 0 | V20: =COUNTIF(SJTA!$S$6:$S$331,T20) -> 0 | W20: =COUNTIF(SPJ!$P$5:$P$136,T20) -> 0 | X20: =COUNTIF(SMP!$P$6:$P$15,T20) -> 0
C21: Pensiunan | D21: =COUNTIF('Data Angt'!$H$5:$H$5710,C21) -> 221 | E21: =D21/$D$27 -> 0.041231343 | T21: Tenaga Ahli | U21: =COUNTIF(SSKA!$Q$7:$Q$466,Rekap!$T21) -> 0 | V21: =COUNTIF(SJTA!$S$6:$S$331,T21) -> 1 | W21: =COUNTIF(SPJ!$P$5:$P$136,T21) -> 0 | X21: =COUNTIF(SMP!$P$6:$P$15,T21) -> 0
C22: Pemuka Agama | D22: =COUNTIF('Data Angt'!$H$5:$H$5710,C22) -> 53 | E22: =D22/$D$27 -> 0.0098880597 | I22: KLASIFIKASI TUJUAN PINJAMAN BERDASAR PROFESI PEMINJAM | T22: Belum/Tidak bekerja | U22: =COUNTIF(SSKA!$Q$7:$Q$466,Rekap!$T22) -> 0 | V22: =COUNTIF(SJTA!$S$6:$S$331,T22) -> 5 | W22: =COUNTIF(SPJ!$P$5:$P$136,T22) -> 1 | X22: =COUNTIF(SMP!$P$6:$P$15,T22) -> 0
C23: Petani/Pekebun/Nelayan/Peternak | D23: =COUNTIF('Data Angt'!$H$5:$H$5710,C23) -> 0 | E23: =D23/$D$27 -> 0 | I23: Profesi | J23: KONSUMTIF | K23: KESEJAHTERAAN | L23: PENDIDIKAN | M23: PRODUKTIF | N23: KESEHATAN | O23: DATA KOSONG | P23: JML | T23: Data Kosong | U23: =COUNTIF(SSKA!$Q$7:$Q$466,0) -> 0 | V23: =COUNTIF(SJTA!$S$6:$S$331,0) -> 11 | W23: =COUNTIF(SPJ!$P$5:$P$136,0) -> 1 | X23: =COUNTIF(SMP!$P$6:$P$15,0) -> 0
C24: Tenaga Ahli | D24: =COUNTIF('Data Angt'!$H$5:$H$5710,C24) -> 20 | E24: =D24/$D$27 -> 0.0037313433 | I24: Karyawan | J24: =COUNTIFS(Pinjaman!$W$6:$W$1373,J$23,Pinjaman!$X$6:$X$1373,$I24) -> 110 | K24: =COUNTIFS(Pinjaman!$W$6:$W$1373,K$23,Pinjaman!$X$6:$X$1373,$I24) -> 100 | L24: =COUNTIFS(Pinjaman!$W$6:$W$1373,L$23,Pinjaman!$X$6:$X$1373,$I24) -> 58 | M24: =COUNTIFS(Pinjaman!$W$6:$W$1373,M$23,Pinjaman!$X$6:$X$1373,$I24) -> 102 | N24: =COUNTIFS(Pinjaman!$W$6:$W$1373,N$23,Pinjaman!$X$6:$X$1373,$I24) -> 5 | O24: =COUNTIFS(Pinjaman!$W$6:$W$1373,0,Pinjaman!$X$6:$X$1373,$I24) -> 15 | P24: =SUM(J24:O24) -> 390 | T24: JUMLAH | U24: =SUM(U11:U23) -> 0 | V24: =SUM(V11:V23) -> 293 | W24: =SUM(W11:W23) -> 119 | X24: =SUM(X11:X23) -> 8
C25: Belum/Tidak bekerja | D25: =COUNTIF('Data Angt'!$H$5:$H$5710,C25) -> 86 | E25: =D25/$D$27 -> 0.016044776 | I25: Wiraswasta | J25: =COUNTIFS(Pinjaman!$W$6:$W$1373,J$23,Pinjaman!$X$6:$X$1373,$I25) -> 56 | K25: =COUNTIFS(Pinjaman!$W$6:$W$1373,K$23,Pinjaman!$X$6:$X$1373,$I25) -> 41 | L25: =COUNTIFS(Pinjaman!$W$6:$W$1373,L$23,Pinjaman!$X$6:$X$1373,$I25) -> 45 | M25: =COUNTIFS(Pinjaman!$W$6:$W$1373,M$23,Pinjaman!$X$6:$X$1373,$I25) -> 241 | N25: =COUNTIFS(Pinjaman!$W$6:$W$1373,N$23,Pinjaman!$X$6:$X$1373,$I25) -> 4 | O25: =COUNTIFS(Pinjaman!$W$6:$W$1373,0,Pinjaman!$X$6:$X$1373,$I25) -> 27 | P25: =SUM(J25:O25) -> 414
C26: Data Kosong | D26: =COUNTIF('Data Angt'!$H$5:$H$5710,"") -> 297 | E26: =D26/$D$27 -> 0.055410448 | I26: Pelajar/Mahasiswa | J26: =COUNTIFS(Pinjaman!$W$6:$W$1373,J$23,Pinjaman!$X$6:$X$1373,$I26) -> 4 | K26: =COUNTIFS(Pinjaman!$W$6:$W$1373,K$23,Pinjaman!$X$6:$X$1373,$I26) -> 0 | L26: =COUNTIFS(Pinjaman!$W$6:$W$1373,L$23,Pinjaman!$X$6:$X$1373,$I26) -> 1 | M26: =COUNTIFS(Pinjaman!$W$6:$W$1373,M$23,Pinjaman!$X$6:$X$1373,$I26) -> 4 | N26: =COUNTIFS(Pinjaman!$W$6:$W$1373,N$23,Pinjaman!$X$6:$X$1373,$I26) -> 0 | O26: =COUNTIFS(Pinjaman!$W$6:$W$1373,0,Pinjaman!$X$6:$X$1373,$I26) -> 0 | P26: =SUM(J26:O26) -> 9 | S26: Usia | T26: Profesi | U26: SSKA | V26: SJTA | W26: SPJ | X26: SMP
C27: JUMLAH | D27: =SUM(D13:D26) -> 5360 | E27: =D27/$D$27 -> 1 | I27: Mengurus Rumah Tangga | J27: =COUNTIFS(Pinjaman!$W$6:$W$1373,J$23,Pinjaman!$X$6:$X$1373,$I27) -> 46 | K27: =COUNTIFS(Pinjaman!$W$6:$W$1373,K$23,Pinjaman!$X$6:$X$1373,$I27) -> 25 | L27: =COUNTIFS(Pinjaman!$W$6:$W$1373,L$23,Pinjaman!$X$6:$X$1373,$I27) -> 26 | M27: =COUNTIFS(Pinjaman!$W$6:$W$1373,M$23,Pinjaman!$X$6:$X$1373,$I27) -> 71 | N27: =COUNTIFS(Pinjaman!$W$6:$W$1373,N$23,Pinjaman!$X$6:$X$1373,$I27) -> 3 | O27: =COUNTIFS(Pinjaman!$W$6:$W$1373,0,Pinjaman!$X$6:$X$1373,$I27) -> 13 | P27: =SUM(J27:O27) -> 184 | S27: <= 23 | T27: Karyawan | U27: =COUNTIFS(SSKA!$Q$7:$Q$466,Rekap!$T27,SSKA!$P$7:$P$466,"<24") -> 0 | V27: =COUNTIFS(SJTA!$S$6:$S$331,T27,SJTA!$R$6:$R$331,"<24") -> 1 | W27: =COUNTIFS(SPJ!$P$5:$P$136,T27,SPJ!O$5:O$136,"<24") -> 0 | X27: =COUNTIFS(SMP!$P$6:$P$15,T27,SMP!$O$6:$O$15,"<24") -> 0
I28: Tenaga Pengajar | J28: =COUNTIFS(Pinjaman!$W$6:$W$1373,J$23,Pinjaman!$X$6:$X$1373,$I28) -> 33 | K28: =COUNTIFS(Pinjaman!$W$6:$W$1373,K$23,Pinjaman!$X$6:$X$1373,$I28) -> 20 | L28: =COUNTIFS(Pinjaman!$W$6:$W$1373,L$23,Pinjaman!$X$6:$X$1373,$I28) -> 34 | M28: =COUNTIFS(Pinjaman!$W$6:$W$1373,M$23,Pinjaman!$X$6:$X$1373,$I28) -> 33 | N28: =COUNTIFS(Pinjaman!$W$6:$W$1373,N$23,Pinjaman!$X$6:$X$1373,$I28) -> 0 | O28: =COUNTIFS(Pinjaman!$W$6:$W$1373,0,Pinjaman!$X$6:$X$1373,$I28) -> 4 | P28: =SUM(J28:O28) -> 124 | T28: Wiraswasta | U28: =COUNTIFS(SSKA!$Q$7:$Q$466,Rekap!$T28,SSKA!$P$7:$P$466,"<24") -> 0 | V28: =COUNTIFS(SJTA!$S$6:$S$331,T28,SJTA!$R$6:$R$331,"<24") -> 0 | W28: =COUNTIFS(SPJ!$P$5:$P$136,T28,SPJ!O$5:O$136,"<24") -> 0 | X28: =COUNTIFS(SMP!$P$6:$P$15,T28,SMP!$O$6:$O$15,"<24") -> 0
B29: KLASIFIKASI PROFESI & USIA ANGGOTA | I29: Lain-Lain | J29: =COUNTIFS(Pinjaman!$W$6:$W$1373,J$23,Pinjaman!$X$6:$X$1373,$I29) -> 22 | K29: =COUNTIFS(Pinjaman!$W$6:$W$1373,K$23,Pinjaman!$X$6:$X$1373,$I29) -> 19 | L29: =COUNTIFS(Pinjaman!$W$6:$W$1373,L$23,Pinjaman!$X$6:$X$1373,$I29) -> 15 | M29: =COUNTIFS(Pinjaman!$W$6:$W$1373,M$23,Pinjaman!$X$6:$X$1373,$I29) -> 25 | N29: =COUNTIFS(Pinjaman!$W$6:$W$1373,N$23,Pinjaman!$X$6:$X$1373,$I29) -> 2 | O29: =COUNTIFS(Pinjaman!$W$6:$W$1373,0,Pinjaman!$X$6:$X$1373,$I29) -> 3 | P29: =SUM(J29:O29) -> 86 | T29: Pelajar/Mahasiswa | U29: =COUNTIFS(SSKA!$Q$7:$Q$466,Rekap!$T29,SSKA!$P$7:$P$466,"<24") -> 0 | V29: =COUNTIFS(SJTA!$S$6:$S$331,T29,SJTA!$R$6:$R$331,"<24") -> 22 | W29: =COUNTIFS(SPJ!$P$5:$P$136,T29,SPJ!O$5:O$136,"<24") -> 9 | X29: =COUNTIFS(SMP!$P$6:$P$15,T29,SMP!$O$6:$O$15,"<24") -> 0
B30: USIA | C30: Profesi | D30: Jml Agt | E30: % | I30: Aparatur Negara | J30: =COUNTIFS(Pinjaman!$W$6:$W$1373,J$23,Pinjaman!$X$6:$X$1373,$I30) -> 0 | K30: =COUNTIFS(Pinjaman!$W$6:$W$1373,K$23,Pinjaman!$X$6:$X$1373,$I30) -> 0 | L30: =COUNTIFS(Pinjaman!$W$6:$W$1373,L$23,Pinjaman!$X$6:$X$1373,$I30) -> 0 | M30: =COUNTIFS(Pinjaman!$W$6:$W$1373,M$23,Pinjaman!$X$6:$X$1373,$I30) -> 0 | N30: =COUNTIFS(Pinjaman!$W$6:$W$1373,N$23,Pinjaman!$X$6:$X$1373,$I30) -> 0 | O30: =COUNTIFS(Pinjaman!$W$6:$W$1373,0,Pinjaman!$X$6:$X$1373,$I30) -> 0 | P30: =SUM(J30:O30) -> 0 | T30: Mengurus Rumah Tangga | U30: =COUNTIFS(SSKA!$Q$7:$Q$466,Rekap!$T30,SSKA!$P$7:$P$466,"<24") -> 0 | V30: =COUNTIFS(SJTA!$S$6:$S$331,T30,SJTA!$R$6:$R$331,"<24") -> 0 | W30: =COUNTIFS(SPJ!$P$5:$P$136,T30,SPJ!O$5:O$136,"<24") -> 0 | X30: =COUNTIFS(SMP!$P$6:$P$15,T30,SMP!$O$6:$O$15,"<24") -> 0
B31: < 17 | C31: Karyawan | D31: =COUNTIFS('Data Angt'!$H$5:$H$5710,C31,'Data Angt'!$F$5:$F$5710,"<17") -> 1 | E31: =D31/$D$27 -> 0.00018656716 | I31: Pensiunan | J31: =COUNTIFS(Pinjaman!$W$6:$W$1373,J$23,Pinjaman!$X$6:$X$1373,$I31) -> 19 | K31: =COUNTIFS(Pinjaman!$W$6:$W$1373,K$23,Pinjaman!$X$6:$X$1373,$I31) -> 10 | L31: =COUNTIFS(Pinjaman!$W$6:$W$1373,L$23,Pinjaman!$X$6:$X$1373,$I31) -> 6 | M31: =COUNTIFS(Pinjaman!$W$6:$W$1373,M$23,Pinjaman!$X$6:$X$1373,$I31) -> 13 | N31: =COUNTIFS(Pinjaman!$W$6:$W$1373,N$23,Pinjaman!$X$6:$X$1373,$I31) -> 2 | O31: =COUNTIFS(Pinjaman!$W$6:$W$1373,0,Pinjaman!$X$6:$X$1373,$I31) -> 1 | P31: =SUM(J31:O31) -> 51 | T31: Tenaga Pengajar | U31: =COUNTIFS(SSKA!$Q$7:$Q$466,Rekap!$T31,SSKA!$P$7:$P$466,"<24") -> 0 | V31: =COUNTIFS(SJTA!$S$6:$S$331,T31,SJTA!$R$6:$R$331,"<24") -> 0 | W31: =COUNTIFS(SPJ!$P$5:$P$136,T31,SPJ!O$5:O$136,"<24") -> 0 | X31: =COUNTIFS(SMP!$P$6:$P$15,T31,SMP!$O$6:$O$15,"<24") -> 0
C32: Wiraswasta | D32: =COUNTIFS('Data Angt'!$H$5:$H$5710,C32,'Data Angt'!$F$5:$F$5710,"<17") -> 0 | E32: =D32/$D$27 -> 0 | H32: USIA | I32: Pemuka Agama | J32: =COUNTIFS(Pinjaman!$W$6:$W$1373,J$23,Pinjaman!$X$6:$X$1373,$I32) -> 0 | K32: =COUNTIFS(Pinjaman!$W$6:$W$1373,K$23,Pinjaman!$X$6:$X$1373,$I32) -> 0 | L32: =COUNTIFS(Pinjaman!$W$6:$W$1373,L$23,Pinjaman!$X$6:$X$1373,$I32) -> 0 | M32: =COUNTIFS(Pinjaman!$W$6:$W$1373,M$23,Pinjaman!$X$6:$X$1373,$I32) -> 1 | N32: =COUNTIFS(Pinjaman!$W$6:$W$1373,N$23,Pinjaman!$X$6:$X$1373,$I32) -> 0 | O32: =COUNTIFS(Pinjaman!$W$6:$W$1373,0,Pinjaman!$X$6:$X$1373,$I32) -> 0 | P32: =SUM(J32:O32) -> 1 | T32: Lain-Lain | U32: =COUNTIFS(SSKA!$Q$7:$Q$466,Rekap!$T32,SSKA!$P$7:$P$466,"<24") -> 0 | V32: =COUNTIFS(SJTA!$S$6:$S$331,T32,SJTA!$R$6:$R$331,"<24") -> 0 | W32: =COUNTIFS(SPJ!$P$5:$P$136,T32,SPJ!O$5:O$136,"<24") -> 0 | X32: =COUNTIFS(SMP!$P$6:$P$15,T32,SMP!$O$6:$O$15,"<24") -> 0
C33: Pelajar/Mahasiswa | D33: =COUNTIFS('Data Angt'!$H$5:$H$5710,C33,'Data Angt'!$F$5:$F$5710,"<17") -> 8 | E33: =D33/$D$27 -> 0.0014925373 | H33: < =23 | I33: Petani/Pekebun/Nelayan/Peternak | J33: =COUNTIFS(Pinjaman!$W$6:$W$1373,J$23,Pinjaman!$X$6:$X$1373,$I33) -> 0 | K33: =COUNTIFS(Pinjaman!$W$6:$W$1373,K$23,Pinjaman!$X$6:$X$1373,$I33) -> 0 | L33: =COUNTIFS(Pinjaman!$W$6:$W$1373,L$23,Pinjaman!$X$6:$X$1373,$I33) -> 0 | M33: =COUNTIFS(Pinjaman!$W$6:$W$1373,M$23,Pinjaman!$X$6:$X$1373,$I33) -> 0 | N33: =COUNTIFS(Pinjaman!$W$6:$W$1373,N$23,Pinjaman!$X$6:$X$1373,$I33) -> 0 | O33: =COUNTIFS(Pinjaman!$W$6:$W$1373,0,Pinjaman!$X$6:$X$1373,$I33) -> 0 | P33: =SUM(J33:O33) -> 0 | T33: Aparatur Negara | U33: =COUNTIFS(SSKA!$Q$7:$Q$466,Rekap!$T33,SSKA!$P$7:$P$466,"<24") -> 0 | V33: =COUNTIFS(SJTA!$S$6:$S$331,T33,SJTA!$R$6:$R$331,"<24") -> 0 | W33: =COUNTIFS(SPJ!$P$5:$P$136,T33,SPJ!O$5:O$136,"<24") -> 0 | X33: =COUNTIFS(SMP!$P$6:$P$15,T33,SMP!$O$6:$O$15,"<24") -> 0
C34: Mengurus Rumah Tangga | D34: =COUNTIFS('Data Angt'!$H$5:$H$5710,C34,'Data Angt'!$F$5:$F$5710,"<17") -> 0 | E34: =D34/$D$27 -> 0 | I34: Tenaga Ahli | J34: =COUNTIFS(Pinjaman!$W$6:$W$1373,J$23,Pinjaman!$X$6:$X$1373,$I34) -> 1 | K34: =COUNTIFS(Pinjaman!$W$6:$W$1373,K$23,Pinjaman!$X$6:$X$1373,$I34) -> 1 | L34: =COUNTIFS(Pinjaman!$W$6:$W$1373,L$23,Pinjaman!$X$6:$X$1373,$I34) -> 0 | M34: =COUNTIFS(Pinjaman!$W$6:$W$1373,M$23,Pinjaman!$X$6:$X$1373,$I34) -> 2 | N34: =COUNTIFS(Pinjaman!$W$6:$W$1373,N$23,Pinjaman!$X$6:$X$1373,$I34) -> 0 | O34: =COUNTIFS(Pinjaman!$W$6:$W$1373,0,Pinjaman!$X$6:$X$1373,$I34) -> 0 | P34: =SUM(J34:O34) -> 4 | T34: Pensiunan | U34: =COUNTIFS(SSKA!$Q$7:$Q$466,Rekap!$T34,SSKA!$P$7:$P$466,"<24") -> 0 | V34: =COUNTIFS(SJTA!$S$6:$S$331,T34,SJTA!$R$6:$R$331,"<24") -> 0 | W34: =COUNTIFS(SPJ!$P$5:$P$136,T34,SPJ!O$5:O$136,"<24") -> 0 | X34: =COUNTIFS(SMP!$P$6:$P$15,T34,SMP!$O$6:$O$15,"<24") -> 0
C35: Tenaga Pengajar | D35: =COUNTIFS('Data Angt'!$H$5:$H$5710,C35,'Data Angt'!$F$5:$F$5710,"<17") -> 0 | E35: =D35/$D$27 -> 0 | I35: Belum/Tidak bekerja | J35: =COUNTIFS(Pinjaman!$W$6:$W$1373,J$23,Pinjaman!$X$6:$X$1373,$I35) -> 1 | K35: =COUNTIFS(Pinjaman!$W$6:$W$1373,K$23,Pinjaman!$X$6:$X$1373,$I35) -> 0 | L35: =COUNTIFS(Pinjaman!$W$6:$W$1373,L$23,Pinjaman!$X$6:$X$1373,$I35) -> 1 | M35: =COUNTIFS(Pinjaman!$W$6:$W$1373,M$23,Pinjaman!$X$6:$X$1373,$I35) -> 3 | N35: =COUNTIFS(Pinjaman!$W$6:$W$1373,N$23,Pinjaman!$X$6:$X$1373,$I35) -> 0 | O35: =COUNTIFS(Pinjaman!$W$6:$W$1373,0,Pinjaman!$X$6:$X$1373,$I35) -> 0 | P35: =SUM(J35:O35) -> 5 | T35: Pemuka Agama | U35: =COUNTIFS(SSKA!$Q$7:$Q$466,Rekap!$T35,SSKA!$P$7:$P$466,"<24") -> 0 | V35: =COUNTIFS(SJTA!$S$6:$S$331,T35,SJTA!$R$6:$R$331,"<24") -> 0 | W35: =COUNTIFS(SPJ!$P$5:$P$136,T35,SPJ!O$5:O$136,"<24") -> 0 | X35: =COUNTIFS(SMP!$P$6:$P$15,T35,SMP!$O$6:$O$15,"<24") -> 0
C36: Lain-Lain | D36: =COUNTIFS('Data Angt'!$H$5:$H$5710,C36,'Data Angt'!$F$5:$F$5710,"<17") -> 0 | E36: =D36/$D$27 -> 0 | I36: Data Kosong | J36: =COUNTIFS(Pinjaman!$W$6:$W$1373,J$23,Pinjaman!$X$6:$X$1373,0) -> 4 | K36: =COUNTIFS(Pinjaman!$W$6:$W$1373,K$23,Pinjaman!$X$6:$X$1373,0) -> 4 | L36: =COUNTIFS(Pinjaman!$W$6:$W$1373,L$23,Pinjaman!$X$6:$X$1373,0) -> 2 | M36: =COUNTIFS(Pinjaman!$W$6:$W$1373,M$23,Pinjaman!$X$6:$X$1373,0) -> 6 | N36: =COUNTIFS(Pinjaman!$W$6:$W$1373,N$23,Pinjaman!$X$6:$X$1373,0) -> 0 | O36: =COUNTIFS(Pinjaman!$W$6:$W$1373,0,Pinjaman!$X$6:$X$1373,0) -> 1 | P36: =SUM(J36:O36) -> 17 | T36: Petani/Pekebun/Nelayan/Peternak | U36: =COUNTIFS(SSKA!$Q$7:$Q$466,Rekap!$T36,SSKA!$P$7:$P$466,"<24") -> 0 | V36: =COUNTIFS(SJTA!$S$6:$S$331,T36,SJTA!$R$6:$R$331,"<24") -> 0 | W36: =COUNTIFS(SPJ!$P$5:$P$136,T36,SPJ!O$5:O$136,"<24") -> 0 | X36: =COUNTIFS(SMP!$P$6:$P$15,T36,SMP!$O$6:$O$15,"<24") -> 0
C37: Aparatur Negara | D37: =COUNTIFS('Data Angt'!$H$5:$H$5710,C37,'Data Angt'!$F$5:$F$5710,"<17") -> 0 | E37: =D37/$D$27 -> 0 | I37: JUMLAH | J37: =SUM(J24:J36) -> 296 | K37: =SUM(K24:K36) -> 220 | L37: =SUM(L24:L36) -> 188 | M37: =SUM(M24:M36) -> 501 | N37: =SUM(N24:N36) -> 16 | O37: =SUM(O24:O36) -> 64 | P37: =SUM(P24:P36) -> 1285 | T37: Tenaga Ahli | U37: =COUNTIFS(SSKA!$Q$7:$Q$466,Rekap!$T37,SSKA!$P$7:$P$466,"<24") -> 0 | V37: =COUNTIFS(SJTA!$S$6:$S$331,T37,SJTA!$R$6:$R$331,"<24") -> 0 | W37: =COUNTIFS(SPJ!$P$5:$P$136,T37,SPJ!O$5:O$136,"<24") -> 0 | X37: =COUNTIFS(SMP!$P$6:$P$15,T37,SMP!$O$6:$O$15,"<24") -> 0
C38: Pensiunan | D38: =COUNTIFS('Data Angt'!$H$5:$H$5710,C38,'Data Angt'!$F$5:$F$5710,"<17") -> 0 | E38: =D38/$D$27 -> 0 | T38: Belum/Tidak bekerja | U38: =COUNTIFS(SSKA!$Q$7:$Q$466,Rekap!$T38,SSKA!$P$7:$P$466,"<24") -> 0 | V38: =COUNTIFS(SJTA!$S$6:$S$331,T38,SJTA!$R$6:$R$331,"<24") -> 1 | W38: =COUNTIFS(SPJ!$P$5:$P$136,T38,SPJ!O$5:O$136,"<24") -> 0 | X38: =COUNTIFS(SMP!$P$6:$P$15,T38,SMP!$O$6:$O$15,"<24") -> 0
C39: Pemuka Agama | D39: =COUNTIFS('Data Angt'!$H$5:$H$5710,C39,'Data Angt'!$F$5:$F$5710,"<17") -> 0 | E39: =D39/$D$27 -> 0 | T39: Data Kosong | U39: =COUNTIFS(SSKA!$Q$7:$Q$466,0,SSKA!$P$7:$P$466,"<24") -> 0 | V39: =COUNTIFS(SJTA!$S$6:$S$331,0,SJTA!$R$6:$R$331,"<24") -> 3 | W39: =COUNTIFS(SPJ!$P$5:$P$136,0,SPJ!O$5:O$136,"<24") -> 0 | X39: =COUNTIFS(SMP!$P$6:$P$15,0,SMP!$O$6:$O$15,"<24") -> 0
C40: Petani/Pekebun/Nelayan/Peternak | D40: =COUNTIFS('Data Angt'!$H$5:$H$5710,C40,'Data Angt'!$F$5:$F$5710,"<17") -> 0 | E40: =D40/$D$27 -> 0 | I40: Profesi | J40: KONSUMTIF | K40: KESEJAHTERAAN | L40: PENDIDIKAN | M40: PRODUKTIF | N40: KESEHATAN | O40: DATA KOSONG | P40: JML | T40: JUMLAH | U40: =SUM(U27:U39) -> 0 | V40: =SUM(V27:V39) -> 27 | W40: =SUM(W27:W39) -> 9 | X40: =SUM(X27:X39) -> 0
C41: Tenaga Ahli | D41: =COUNTIFS('Data Angt'!$H$5:$H$5710,C41,'Data Angt'!$F$5:$F$5710,"<17") -> 0 | E41: =D41/$D$27 -> 0 | I41: Karyawan | J41: =COUNTIFS(Pinjaman!$X$6:$X$1373,$I41,Pinjaman!$W$6:$W$1373,J$40,Pinjaman!$V$6:$V$1373,"<24") -> 9 | K41: =COUNTIFS(Pinjaman!$X$6:$X$1373,$I41,Pinjaman!$W$6:$W$1373,K$40,Pinjaman!$V$6:$V$1373,"<24") -> 5 | L41: =COUNTIFS(Pinjaman!$X$6:$X$1373,$I41,Pinjaman!$W$6:$W$1373,L$40,Pinjaman!$V$6:$V$1373,"<24") -> 0 | M41: =COUNTIFS(Pinjaman!$X$6:$X$1373,$I41,Pinjaman!$W$6:$W$1373,M$40,Pinjaman!$V$6:$V$1373,"<24") -> 1 | N41: =COUNTIFS(Pinjaman!$X$6:$X$1373,$I41,Pinjaman!$W$6:$W$1373,N$40,Pinjaman!$V$6:$V$1373,"<24") -> 0 | O41: =COUNTIFS(Pinjaman!$X$6:$X$1373,$I41,Pinjaman!$W$6:$W$1373,0,Pinjaman!$V$6:$V$1373,"<24") -> 0 | P41: =SUM(J41:O41) -> 15 | S41: 24 - 60 | T41: Karyawan | U41: =COUNTIFS(SSKA!$Q$7:$Q$466,Rekap!$T41,SSKA!$P$7:$P$466,"<=60")-COUNTIFS(SSKA!$Q$7:$Q$466,Rekap!$T41,SSKA!$P$7:$P$466,"<24") -> 0 | V41: =COUNTIFS(SJTA!$S$6:$S$331,T41,SJTA!$R$6:$R$331,"<=60")-COUNTIFS(SJTA!$S$6:$S$331,T41,SJTA!$R$6:$R$331,"<24") -> 66 | W41: =COUNTIFS(SPJ!$P$5:$P$136,T27,SPJ!O$5:O$136,"<=60")-COUNTIFS(SPJ!$P$5:$P$136,T27,SPJ!O$5:O$136,"<24") -> 33 | X41: =COUNTIFS(SMP!$P$6:$P$15,T41,SMP!$O$6:$O$15,"<=60")-COUNTIFS(SMP!$P$6:$P$15,T41,SMP!$O$6:$O$15,"<24") -> 4
...

Sheet ANALISA
A2: 1 | B2: KLASIFIKASI USIA KESELURUHAN ANGGOTA | M2: ANGGOTA BARU 2025
M3: USIA | N3: GAB | P3: PBL | R3: KRK | T3: JBR | V3: BWI | X3: MJK | Z3: MGL
B4: USIA | C4: JUMLAH | D4: % | E4: PBL | F4: KRK | G4: JBR | H4: BWI | I4: MJK | J4: MGL | K4: PML | M4: <24 th | N4: =COUNTIF('2025'!$I$3:$I$649,"<24") -> 82 | O4: =N4/$N$9 -> 0.12673879 | P4: =COUNTIFS('2025'!$F$3:$F$649,"001",'2025'!$I$3:$I$649,"<24") -> 48 | Q4: =P4/P$9 -> 0.17977528 | R4: =COUNTIFS('2025'!$F$3:$F$649,"002",'2025'!$I$3:$I$649,"<24") -> 4 | S4: =R4/R$9 -> 0.042553191 | T4: =COUNTIFS('2025'!$F$3:$F$649,"003",'2025'!$I$3:$I$649,"<24") -> 6 | U4: =T4/T$9 -> 0.068181818 | V4: =COUNTIFS('2025'!$F$3:$F$649,"004",'2025'!$I$3:$I$649,"<24") -> 12 | W4: =V4/V$9 -> 0.14457831 | X4: =COUNTIFS('2025'!$F$3:$F$649,"005",'2025'!$I$3:$I$649,"<24") -> 7 | Y4: =X4/X$9 -> 0.1 | Z4: =COUNTIFS('2025'!$F$3:$F$649,"006",'2025'!$I$3:$I$649,"<24") -> 5 | AA4: =Z4/Z$9 -> 0.11111111
B5: <24 th | C5: =COUNTIF('Data Angt'!$F$5:$F$5809,"<24") -> 342 | D5: =C5/$C$11 -> 0.058914729 | E5: =COUNTIFS('Data Angt'!$C$5:$C$5809,E$4,'Data Angt'!$F$5:$F$5809,"<24") -> 166 | F5: =COUNTIFS('Data Angt'!$C$5:$C$5809,F$4,'Data Angt'!$F$5:$F$5809,"<24") -> 27 | G5: =COUNTIFS('Data Angt'!$C$5:$C$5809,G$4,'Data Angt'!$F$5:$F$5809,"<24") -> 50 | H5: =COUNTIFS('Data Angt'!$C$5:$C$5809,H$4,'Data Angt'!$F$5:$F$5809,"<24") -> 39 | I5: =COUNTIFS('Data Angt'!$C$5:$C$5809,I$4,'Data Angt'!$F$5:$F$5809,"<24") -> 34 | J5: =COUNTIFS('Data Angt'!$C$5:$C$5809,J$4,'Data Angt'!$F$5:$F$5809,"<24") -> 26 | K5: =COUNTIFS('Data Angt'!$C$5:$C$5809,K$4,'Data Angt'!$F$5:$F$5809,"<24") -> 0 | M5: 24 - 35 th | N5: =COUNTIF('2025'!$I$3:$I$649,"<=35")-COUNTIF('2025'!$I$3:$I$649,"<24") -> 159 | O5: =N5/$N$9 -> 0.24574961 | P5: =COUNTIFS('2025'!$F$3:$F$649,"001",'2025'!$I$3:$I$649,"<=35")-COUNTIFS('2025'!$F$3:$F$649,"001",'2025'!$I$3:$I$649,"<24") -> 81 | Q5: =P5/P$9 -> 0.30337079 | R5: =COUNTIFS('2025'!$F$3:$F$649,"002",'2025'!$I$3:$I$649,"<=35")-COUNTIFS('2025'!$F$3:$F$649,"002",'2025'!$I$3:$I$649,"<24") -> 15 | S5: =R5/R$9 -> 0.15957447 | T5: =COUNTIFS('2025'!$F$3:$F$649,"003",'2025'!$I$3:$I$649,"<=35")-COUNTIFS('2025'!$F$3:$F$649,"003",'2025'!$I$3:$I$649,"<24") -> 22 | U5: =T5/T$9 -> 0.25 | V5: =COUNTIFS('2025'!$F$3:$F$649,"004",'2025'!$I$3:$I$649,"<=35")-COUNTIFS('2025'!$F$3:$F$649,"004",'2025'!$I$3:$I$649,"<24") -> 27 | W5: =V5/V$9 -> 0.3253012 | X5: =COUNTIFS('2025'!$F$3:$F$649,"005",'2025'!$I$3:$I$649,"<=35")-COUNTIFS('2025'!$F$3:$F$649,"005",'2025'!$I$3:$I$649,"<24") -> 4 | Y5: =X5/X$9 -> 0.057142857 | Z5: =COUNTIFS('2025'!$F$3:$F$649,"006",'2025'!$I$3:$I$649,"<=35")-COUNTIFS('2025'!$F$3:$F$649,"006",'2025'!$I$3:$I$649,"<24") -> 10 | AA5: =Z5/Z$9 -> 0.22222222
B6: 24 - 35 th | C6: =COUNTIF('Data Angt'!$F$5:$F$5809,"<=35")-COUNTIF('Data Angt'!$F$5:$F$5809,"<24") -> 1006 | D6: =C6/$C$11 -> 0.17329888 | E6: =COUNTIFS('Data Angt'!$C$5:$C$5809,E$4,'Data Angt'!$F$5:$F$5809,"<=35")-COUNTIFS('Data Angt'!$C$5:$C$5809,E$4,'Data Angt'!$F$5:$F$5809,"<24") -> 513 | F6: =COUNTIFS('Data Angt'!$C$5:$C$5809,F$4,'Data Angt'!$F$5:$F$5809,"<=35")-COUNTIFS('Data Angt'!$C$5:$C$5809,F$4,'Data Angt'!$F$5:$F$5809,"<24") -> 105 | G6: =COUNTIFS('Data Angt'!$C$5:$C$5809,G$4,'Data Angt'!$F$5:$F$5809,"<=35")-COUNTIFS('Data Angt'!$C$5:$C$5809,G$4,'Data Angt'!$F$5:$F$5809,"<24") -> 164 | H6: =COUNTIFS('Data Angt'!$C$5:$C$5809,H$4,'Data Angt'!$F$5:$F$5809,"<=35")-COUNTIFS('Data Angt'!$C$5:$C$5809,H$4,'Data Angt'!$F$5:$F$5809,"<24") -> 112 | I6: =COUNTIFS('Data Angt'!$C$5:$C$5809,I$4,'Data Angt'!$F$5:$F$5809,"<=35")-COUNTIFS('Data Angt'!$C$5:$C$5809,I$4,'Data Angt'!$F$5:$F$5809,"<24") -> 46 | J6: =COUNTIFS('Data Angt'!$C$5:$C$5809,J$4,'Data Angt'!$F$5:$F$5809,"<=35")-COUNTIFS('Data Angt'!$C$5:$C$5809,J$4,'Data Angt'!$F$5:$F$5809,"<24") -> 62 | K6: =COUNTIFS('Data Angt'!$C$5:$C$5809,K$4,'Data Angt'!$F$5:$F$5809,"<=35")-COUNTIFS('Data Angt'!$C$5:$C$5809,K$4,'Data Angt'!$F$5:$F$5809,"<24") -> 4 | M6: 36 - 45 th | N6: =COUNTIF('2025'!$I$3:$I$649,"<=45")-COUNTIF('2025'!$I$3:$I$649,"<=35") -> 160 | O6: =N6/$N$9 -> 0.24729521 | P6: =COUNTIFS('2025'!$F$3:$F$649,"001",'2025'!$I$3:$I$649,"<=45")-COUNTIFS('2025'!$F$3:$F$649,"001",'2025'!$I$3:$I$649,"<36") -> 51 | Q6: =P6/P$9 -> 0.19101124 | R6: =COUNTIFS('2025'!$F$3:$F$649,"002",'2025'!$I$3:$I$649,"<=45")-COUNTIFS('2025'!$F$3:$F$649,"002",'2025'!$I$3:$I$649,"<36") -> 34 | S6: =R6/R$9 -> 0.36170213 | T6: =COUNTIFS('2025'!$F$3:$F$649,"003",'2025'!$I$3:$I$649,"<=45")-COUNTIFS('2025'!$F$3:$F$649,"003",'2025'!$I$3:$I$649,"<36") -> 23 | U6: =T6/T$9 -> 0.26136364 | V6: =COUNTIFS('2025'!$F$3:$F$649,"004",'2025'!$I$3:$I$649,"<=45")-COUNTIFS('2025'!$F$3:$F$649,"004",'2025'!$I$3:$I$649,"<36") -> 28 | W6: =V6/V$9 -> 0.3373494 | X6: =COUNTIFS('2025'!$F$3:$F$649,"005",'2025'!$I$3:$I$649,"<=45")-COUNTIFS('2025'!$F$3:$F$649,"005",'2025'!$I$3:$I$649,"<36") -> 13 | Y6: =X6/X$9 -> 0.18571429 | Z6: =COUNTIFS('2025'!$F$3:$F$649,"006",'2025'!$I$3:$I$649,"<=45")-COUNTIFS('2025'!$F$3:$F$649,"006",'2025'!$I$3:$I$649,"<36") -> 11 | AA6: =Z6/Z$9 -> 0.24444444
B7: 36 - 45 th | C7: =COUNTIF('Data Angt'!$F$5:$F$5809,"<=45")-COUNTIF('Data Angt'!$F$5:$F$5809,"<=35") -> 1448 | D7: =C7/$C$11 -> 0.24944014 | E7: =COUNTIFS('Data Angt'!$C$5:$C$5809,E$4,'Data Angt'!$F$5:$F$5809,"<=45")-COUNTIFS('Data Angt'!$C$5:$C$5809,E$4,'Data Angt'!$F$5:$F$5809,"<36") -> 653 | F7: =COUNTIFS('Data Angt'!$C$5:$C$5809,F$4,'Data Angt'!$F$5:$F$5809,"<=45")-COUNTIFS('Data Angt'!$C$5:$C$5809,F$4,'Data Angt'!$F$5:$F$5809,"<36") -> 198 | G7: =COUNTIFS('Data Angt'!$C$5:$C$5809,G$4,'Data Angt'!$F$5:$F$5809,"<=45")-COUNTIFS('Data Angt'!$C$5:$C$5809,G$4,'Data Angt'!$F$5:$F$5809,"<36") -> 211 | H7: =COUNTIFS('Data Angt'!$C$5:$C$5809,H$4,'Data Angt'!$F$5:$F$5809,"<=45")-COUNTIFS('Data Angt'!$C$5:$C$5809,H$4,'Data Angt'!$F$5:$F$5809,"<36") -> 113 | I7: =COUNTIFS('Data Angt'!$C$5:$C$5809,I$4,'Data Angt'!$F$5:$F$5809,"<=45")-COUNTIFS('Data Angt'!$C$5:$C$5809,I$4,'Data Angt'!$F$5:$F$5809,"<36") -> 82 | J7: =COUNTIFS('Data Angt'!$C$5:$C$5809,J$4,'Data Angt'!$F$5:$F$5809,"<=45")-COUNTIFS('Data Angt'!$C$5:$C$5809,J$4,'Data Angt'!$F$5:$F$5809,"<36") -> 100 | K7: =COUNTIFS('Data Angt'!$C$5:$C$5809,K$4,'Data Angt'!$F$5:$F$5809,"<=45")-COUNTIFS('Data Angt'!$C$5:$C$5809,K$4,'Data Angt'!$F$5:$F$5809,"<36") -> 91 | M7: 46 - 60 th | N7: =COUNTIF('2025'!$I$3:$I$649,"<=60")-COUNTIF('2025'!$I$3:$I$649,"<=45") -> 206 | O7: =N7/$N$9 -> 0.31839258 | P7: =COUNTIFS('2025'!$F$3:$F$649,"001",'2025'!$I$3:$I$649,"<=60")-COUNTIFS('2025'!$F$3:$F$649,"001",'2025'!$I$3:$I$649,"<46") -> 72 | Q7: =P7/P$9 -> 0.26966292 | R7: =COUNTIFS('2025'!$F$3:$F$649,"002",'2025'!$I$3:$I$649,"<=60")-COUNTIFS('2025'!$F$3:$F$649,"002",'2025'!$I$3:$I$649,"<46") -> 35 | S7: =R7/R$9 -> 0.37234043 | T7: =COUNTIFS('2025'!$F$3:$F$649,"003",'2025'!$I$3:$I$649,"<=60")-COUNTIFS('2025'!$F$3:$F$649,"003",'2025'!$I$3:$I$649,"<46") -> 33 | U7: =T7/T$9 -> 0.375 | V7: =COUNTIFS('2025'!$F$3:$F$649,"004",'2025'!$I$3:$I$649,"<=60")-COUNTIFS('2025'!$F$3:$F$649,"004",'2025'!$I$3:$I$649,"<46") -> 13 | W7: =V7/V$9 -> 0.15662651 | X7: =COUNTIFS('2025'!$F$3:$F$649,"005",'2025'!$I$3:$I$649,"<=60")-COUNTIFS('2025'!$F$3:$F$649,"005",'2025'!$I$3:$I$649,"<46") -> 36 | Y7: =X7/X$9 -> 0.51428571 | Z7: =COUNTIFS('2025'!$F$3:$F$649,"006",'2025'!$I$3:$I$649,"<=60")-COUNTIFS('2025'!$F$3:$F$649,"006",'2025'!$I$3:$I$649,"<46") -> 17 | AA7: =Z7/Z$9 -> 0.37777778
B8: 46 - 60 th | C8: =COUNTIF('Data Angt'!$F$5:$F$5809,"<=60")-COUNTIF('Data Angt'!$F$5:$F$5809,"<=45") -> 2097 | D8: =C8/$C$11 -> 0.36124031 | E8: =COUNTIFS('Data Angt'!$C$5:$C$5809,E$4,'Data Angt'!$F$5:$F$5809,"<=60")-COUNTIFS('Data Angt'!$C$5:$C$5809,E$4,'Data Angt'!$F$5:$F$5809,"<46") -> 874 | F8: =COUNTIFS('Data Angt'!$C$5:$C$5809,F$4,'Data Angt'!$F$5:$F$5809,"<=60")-COUNTIFS('Data Angt'!$C$5:$C$5809,F$4,'Data Angt'!$F$5:$F$5809,"<46") -> 262 | G8: =COUNTIFS('Data Angt'!$C$5:$C$5809,G$4,'Data Angt'!$F$5:$F$5809,"<=60")-COUNTIFS('Data Angt'!$C$5:$C$5809,G$4,'Data Angt'!$F$5:$F$5809,"<46") -> 371 | H8: =COUNTIFS('Data Angt'!$C$5:$C$5809,H$4,'Data Angt'!$F$5:$F$5809,"<=60")-COUNTIFS('Data Angt'!$C$5:$C$5809,H$4,'Data Angt'!$F$5:$F$5809,"<46") -> 155 | I8: =COUNTIFS('Data Angt'!$C$5:$C$5809,I$4,'Data Angt'!$F$5:$F$5809,"<=60")-COUNTIFS('Data Angt'!$C$5:$C$5809,I$4,'Data Angt'!$F$5:$F$5809,"<46") -> 156 | J8: =COUNTIFS('Data Angt'!$C$5:$C$5809,J$4,'Data Angt'!$F$5:$F$5809,"<=60")-COUNTIFS('Data Angt'!$C$5:$C$5809,J$4,'Data Angt'!$F$5:$F$5809,"<46") -> 228 | K8: =COUNTIFS('Data Angt'!$C$5:$C$5809,K$4,'Data Angt'!$F$5:$F$5809,"<=60")-COUNTIFS('Data Angt'!$C$5:$C$5809,K$4,'Data Angt'!$F$5:$F$5809,"<46") -> 51 | M8: > 60 th | N8: =COUNTIF('2025'!$I$3:$I$649,">60") -> 40 | O8: =N8/$N$9 -> 0.061823802 | P8: =COUNTIFS('2025'!$F$3:$F$649,"001",'2025'!$I$3:$I$649,">60") -> 15 | Q8: =P8/P$9 -> 0.056179775 | R8: =COUNTIFS('2025'!$F$3:$F$649,"002",'2025'!$I$3:$I$649,">60") -> 6 | S8: =R8/R$9 -> 0.063829787 | T8: =COUNTIFS('2025'!$F$3:$F$649,"003",'2025'!$I$3:$I$649,">60") -> 4 | U8: =T8/T$9 -> 0.045454545 | V8: =COUNTIFS('2025'!$F$3:$F$649,"004",'2025'!$I$3:$I$649,">60") -> 3 | W8: =V8/V$9 -> 0.036144578 | X8: =COUNTIFS('2025'!$F$3:$F$649,"005",'2025'!$I$3:$I$649,">60") -> 10 | Y8: =X8/X$9 -> 0.14285714 | Z8: =COUNTIFS('2025'!$F$3:$F$649,"006",'2025'!$I$3:$I$649,">60") -> 2 | AA8: =Z8/Z$9 -> 0.044444444
B9: > 60 th | C9: =COUNTIF('Data Angt'!$F$5:$F$5809,">60") -> 870 | D9: =C9/$C$11 -> 0.1498708 | E9: =COUNTIFS('Data Angt'!$C$5:$C$5809,E$4,'Data Angt'!$F$5:$F$5809,">60") -> 410 | F9: =COUNTIFS('Data Angt'!$C$5:$C$5809,F$4,'Data Angt'!$F$5:$F$5809,">60") -> 105 | G9: =COUNTIFS('Data Angt'!$C$5:$C$5809,G$4,'Data Angt'!$F$5:$F$5809,">60") -> 148 | H9: =COUNTIFS('Data Angt'!$C$5:$C$5809,H$4,'Data Angt'!$F$5:$F$5809,">60") -> 61 | I9: =COUNTIFS('Data Angt'!$C$5:$C$5809,I$4,'Data Angt'!$F$5:$F$5809,">60") -> 38 | J9: =COUNTIFS('Data Angt'!$C$5:$C$5809,J$4,'Data Angt'!$F$5:$F$5809,">60") -> 106 | K9: =COUNTIFS('Data Angt'!$C$5:$C$5809,K$4,'Data Angt'!$F$5:$F$5809,">60") -> 2 | M9: TOTAL | N9: =SUM(N4:N8) -> 647 | P9: =SUM(P4:P8) -> 267 | R9: =SUM(R4:R8) -> 94 | T9: =SUM(T4:T8) -> 88 | V9: =SUM(V4:V8) -> 83 | X9: =SUM(X4:X8) -> 70 | Z9: =SUM(Z4:Z8) -> 45
B10: Tidak Valid | C10: =COUNTIF('Data Angt'!$F$5:$F$5809,"#VALUE!") -> 42 | D10: =C10/$C$11 -> 0.0072351421 | E10: =COUNTIFS('Data Angt'!$C$5:$C$5809,E$4,'Data Angt'!$F$5:$F$5809,"#VALUE!") -> 0 | F10: =COUNTIFS('Data Angt'!$C$5:$C$5809,F$4,'Data Angt'!$F$5:$F$5809,"#VALUE!") -> 0 | G10: =COUNTIFS('Data Angt'!$C$5:$C$5809,G$4,'Data Angt'!$F$5:$F$5809,"#VALUE!") -> 0 | H10: =COUNTIFS('Data Angt'!$C$5:$C$5809,H$4,'Data Angt'!$F$5:$F$5809,"#VALUE!") -> 0 | I10: =COUNTIFS('Data Angt'!$C$5:$C$5809,I$4,'Data Angt'!$F$5:$F$5809,"#VALUE!") -> 0 | J10: =COUNTIFS('Data Angt'!$C$5:$C$5809,J$4,'Data Angt'!$F$5:$F$5809,"#VALUE!") -> 0 | K10: =COUNTIFS('Data Angt'!$C$5:$C$5809,K$4,'Data Angt'!$F$5:$F$5809,"#VALUE!") -> 42
B11: TOTAL | C11: =SUM(C5:C10) -> 5805 | E11: =SUM(E5:E10) -> 2616 | F11: =SUM(F5:F10) -> 697 | G11: =SUM(G5:G10) -> 944 | H11: =SUM(H5:H10) -> 480 | I11: =SUM(I5:I10) -> 356 | J11: =SUM(J5:J10) -> 522 | K11: =SUM(K5:K10) -> 190
M12: ANGGOTA BARU 2024
M13: USIA | N13: GAB | P13: PBL | R13: KRK | T13: JBR | V13: BWI | X13: MJK | Z13: MGL | AB13: PM
M14: <24 th | N14: =COUNTIF('2024'!$K$5:$K$908,"<24") -> 83 | O14: =N14/N$20 -> 0.091814159 | P14: =COUNTIFS('2024'!$L$3:$L$908,"001",'2024'!$K$3:$K$908,"<24") -> 44 | Q14: =P14/P$20 -> 0.15068493 | R14: =COUNTIFS('2024'!$L$3:$L$908,"002",'2024'!$K$3:$K$908,"<24") -> 8 | S14: =R14/R$20 -> 0.081632653 | T14: =COUNTIFS('2024'!$L$3:$L$908,"003",'2024'!$K$3:$K$908,"<24") -> 5 | U14: =T14/T$20 -> 0.045454545 | V14: =COUNTIFS('2024'!$L$3:$L$908,"004",'2024'!$K$3:$K$908,"<24") -> 16 | W14: =V14/V$20 -> 0.14953271 | X14: =COUNTIFS('2024'!$L$3:$L$908,"005",'2024'!$K$3:$K$908,"<24") -> 4 | Y14: =X14/X$20 -> 0.072727273 | Z14: =COUNTIFS('2024'!$L$3:$L$908,"006",'2024'!$K$3:$K$908,"<24") -> 6 | AA14: =Z14/Z$20 -> 0.12 | AB14: =COUNTIFS('2024'!$L$3:$L$908,"007",'2024'!$K$3:$K$908,"<24") -> 0 | AC14: =AB14/AB$20 -> 0
M15: 24 - 35 th | N15: =COUNTIF('2024'!$K$5:$K$908,"<=35")-COUNTIF('2024'!$K$5:$K$908,"<24") -> 199 | O15: =N15/N$20 -> 0.22013274 | P15: =COUNTIFS('2024'!$L$3:$L$908,"001",'2024'!$K$3:$K$908,"<=35")-COUNTIFS('2024'!$L$3:$L$908,"001",'2024'!$K$3:$K$908,"<24") -> 89 | Q15: =P15/P$20 -> 0.30479452 | R15: =COUNTIFS('2024'!$L$3:$L$908,"002",'2024'!$K$3:$K$908,"<=35")-COUNTIFS('2024'!$L$3:$L$908,"002",'2024'!$K$3:$K$908,"<24") -> 24 | S15: =R15/R$20 -> 0.24489796 | T15: =COUNTIFS('2024'!$L$3:$L$908,"003",'2024'!$K$3:$K$908,"<=35")-COUNTIFS('2024'!$L$3:$L$908,"003",'2024'!$K$3:$K$908,"<24") -> 28 | U15: =T15/T$20 -> 0.25454545 | V15: =COUNTIFS('2024'!$L$3:$L$908,"004",'2024'!$K$3:$K$908,"<=35")-COUNTIFS('2024'!$L$3:$L$908,"004",'2024'!$K$3:$K$908,"<24") -> 28 | W15: =V15/V$20 -> 0.26168224 | X15: =COUNTIFS('2024'!$L$3:$L$908,"005",'2024'!$K$3:$K$908,"<=35")-COUNTIFS('2024'!$L$3:$L$908,"005",'2024'!$K$3:$K$908,"<24") -> 15 | Y15: =X15/X$20 -> 0.27272727 | Z15: =COUNTIFS('2024'!$L$3:$L$908,"006",'2024'!$K$3:$K$908,"<=35")-COUNTIFS('2024'!$L$3:$L$908,"006",'2024'!$K$3:$K$908,"<24") -> 10 | AA15: =Z15/Z$20 -> 0.2 | AB15: =COUNTIFS('2024'!$L$3:$L$908,"007",'2024'!$K$3:$K$908,"<=35")-COUNTIFS('2024'!$L$3:$L$908,"007",'2024'!$K$3:$K$908,"<24") -> 5 | AC15: =AB15/AB$20 -> 0.026041667
M16: 36 - 45 th | N16: =COUNTIF('2024'!$K$5:$K$908,"<=45")-COUNTIF('2024'!$K$5:$K$908,"<=35") -> 274 | O16: =N16/N$20 -> 0.30309735 | P16: =COUNTIFS('2024'!$L$3:$L$908,"001",'2024'!$K$3:$K$908,"<=45")-COUNTIFS('2024'!$L$3:$L$908,"001",'2024'!$K$3:$K$908,"<36") -> 64 | Q16: =P16/P$20 -> 0.21917808 | R16: =COUNTIFS('2024'!$L$3:$L$908,"002",'2024'!$K$3:$K$908,"<=45")-COUNTIFS('2024'!$L$3:$L$908,"002",'2024'!$K$3:$K$908,"<36") -> 33 | S16: =R16/R$20 -> 0.33673469 | T16: =COUNTIFS('2024'!$L$3:$L$908,"003",'2024'!$K$3:$K$908,"<=45")-COUNTIFS('2024'!$L$3:$L$908,"003",'2024'!$K$3:$K$908,"<36") -> 26 | U16: =T16/T$20 -> 0.23636364 | V16: =COUNTIFS('2024'!$L$3:$L$908,"004",'2024'!$K$3:$K$908,"<=45")-COUNTIFS('2024'!$L$3:$L$908,"004",'2024'!$K$3:$K$908,"<36") -> 26 | W16: =V16/V$20 -> 0.24299065 | X16: =COUNTIFS('2024'!$L$3:$L$908,"005",'2024'!$K$3:$K$908,"<=45")-COUNTIFS('2024'!$L$3:$L$908,"005",'2024'!$K$3:$K$908,"<36") -> 13 | Y16: =X16/X$20 -> 0.23636364 | Z16: =COUNTIFS('2024'!$L$3:$L$908,"006",'2024'!$K$3:$K$908,"<=45")-COUNTIFS('2024'!$L$3:$L$908,"006",'2024'!$K$3:$K$908,"<36") -> 12 | AA16: =Z16/Z$20 -> 0.24 | AB16: =COUNTIFS('2024'!$L$3:$L$908,"007",'2024'!$K$3:$K$908,"<=45")-COUNTIFS('2024'!$L$3:$L$908,"007",'2024'!$K$3:$K$908,"<36") -> 100 | AC16: =AB16/AB$20 -> 0.52083333
M17: 46 - 60 th | N17: =COUNTIF('2024'!$K$5:$K$908,"<=60")-COUNTIF('2024'!$K$5:$K$908,"<=45") -> 260 | O17: =N17/N$20 -> 0.28761062 | P17: =COUNTIFS('2024'!$L$3:$L$908,"001",'2024'!$K$3:$K$908,"<=60")-COUNTIFS('2024'!$L$3:$L$908,"001",'2024'!$K$3:$K$908,"<46") -> 76 | Q17: =P17/P$20 -> 0.26027397 | R17: =COUNTIFS('2024'!$L$3:$L$908,"002",'2024'!$K$3:$K$908,"<=60")-COUNTIFS('2024'!$L$3:$L$908,"002",'2024'!$K$3:$K$908,"<46") -> 29 | S17: =R17/R$20 -> 0.29591837 | T17: =COUNTIFS('2024'!$L$3:$L$908,"003",'2024'!$K$3:$K$908,"<=60")-COUNTIFS('2024'!$L$3:$L$908,"003",'2024'!$K$3:$K$908,"<46") -> 41 | U17: =T17/T$20 -> 0.37272727 | V17: =COUNTIFS('2024'!$L$3:$L$908,"004",'2024'!$K$3:$K$908,"<=60")-COUNTIFS('2024'!$L$3:$L$908,"004",'2024'!$K$3:$K$908,"<46") -> 32 | W17: =V17/V$20 -> 0.29906542 | X17: =COUNTIFS('2024'!$L$3:$L$908,"005",'2024'!$K$3:$K$908,"<=60")-COUNTIFS('2024'!$L$3:$L$908,"005",'2024'!$K$3:$K$908,"<46") -> 21 | Y17: =X17/X$20 -> 0.38181818 | Z17: =COUNTIFS('2024'!$L$3:$L$908,"006",'2024'!$K$3:$K$908,"<=60")-COUNTIFS('2024'!$L$3:$L$908,"006",'2024'!$K$3:$K$908,"<46") -> 19 | AA17: =Z17/Z$20 -> 0.38 | AB17: =COUNTIFS('2024'!$L$3:$L$908,"007",'2024'!$K$3:$K$908,"<=60")-COUNTIFS('2024'!$L$3:$L$908,"007",'2024'!$K$3:$K$908,"<46") -> 42 | AC17: =AB17/AB$20 -> 0.21875
M18: > 60 th | N18: =COUNTIF('2024'!$K$5:$K$908,">60") -> 45 | O18: =N18/N$20 -> 0.049778761 | P18: =COUNTIFS('2024'!$L$3:$L$908,"001",'2024'!$K$3:$K$908,">60") -> 19 | Q18: =P18/P$20 -> 0.065068493 | R18: =COUNTIFS('2024'!$L$3:$L$908,"002",'2024'!$K$3:$K$908,">60") -> 4 | S18: =R18/R$20 -> 0.040816327 | T18: =COUNTIFS('2024'!$L$3:$L$908,"003",'2024'!$K$3:$K$908,">60") -> 10 | U18: =T18/T$20 -> 0.090909091 | V18: =COUNTIFS('2024'!$L$3:$L$908,"004",'2024'!$K$3:$K$908,">60") -> 5 | W18: =V18/V$20 -> 0.046728972 | X18: =COUNTIFS('2024'!$L$3:$L$908,"005",'2024'!$K$3:$K$908,">60") -> 2 | Y18: =X18/X$20 -> 0.036363636 | Z18: =COUNTIFS('2024'!$L$3:$L$908,"006",'2024'!$K$3:$K$908,">60") -> 3 | AA18: =Z18/Z$20 -> 0.06 | AB18: =COUNTIFS('2024'!$L$3:$L$908,"007",'2024'!$K$3:$K$908,">60") -> 2 | AC18: =AB18/AB$20 -> 0.010416667
M19: Tidak Valid | N19: =COUNTIF('2024'!$K$5:$K$908,"/") -> 43 | O19: =N19/N$20 -> 0.047566372 | P19: =COUNTIFS('2024'!$L$3:$L$908,"001",'2024'!$K$3:$K$908,"/") -> 0 | Q19: =P19/P$20 -> 0 | R19: =COUNTIFS('2024'!$L$3:$L$908,"002",'2024'!$K$3:$K$908,"/") -> 0 | S19: =R19/R$20 -> 0 | T19: =COUNTIFS('2024'!$L$3:$L$908,"003",'2024'!$K$3:$K$908,"/") -> 0 | U19: =T19/T$20 -> 0 | V19: =COUNTIFS('2024'!$L$3:$L$908,"004",'2024'!$K$3:$K$908,"/") -> 0 | W19: =V19/V$20 -> 0 | X19: =COUNTIFS('2024'!$L$3:$L$908,"005",'2024'!$K$3:$K$908,"/") -> 0 | Y19: =X19/X$20 -> 0 | Z19: =COUNTIFS('2024'!$L$3:$L$908,"006",'2024'!$K$3:$K$908,"/") -> 0 | AA19: =Z19/Z$20 -> 0 | AB19: =COUNTIFS('2024'!$L$3:$L$908,"007",'2024'!$K$3:$K$908,"/") -> 43 | AC19: =AB19/AB$20 -> 0.22395833
M20: TOTAL | N20: =SUM(N14:N19) -> 904 | P20: =SUM(P14:P19) -> 292 | R20: =SUM(R14:R19) -> 98 | T20: =SUM(T14:T19) -> 110 | V20: =SUM(V14:V19) -> 107 | X20: =SUM(X14:X19) -> 55 | Z20: =SUM(Z14:Z19) -> 50 | AB20: =SUM(AB14:AB19) -> 192
A25: 2 | B25: KLASIFIKASI ANGGOTA BERDASARKAN PROFESI
B27: PROFESI | C27: JUMLAH | D27: % | E27: PBL | F27: KRK | G27: JBR | H27: BWI | I27: MJK | J27: MGL | K27: PML
B28: Wiraswasta | C28: =COUNTIF('Data Angt'!$H$5:$H$5809,B28) -> 1369 | D28: =C28/$C$42 -> 0.23583118 | E28: =COUNTIFS('Data Angt'!$C$5:$C$5809,E$27,'Data Angt'!$H$5:$H$5809,$B28) -> 544 | F28: =COUNTIFS('Data Angt'!$C$5:$C$5809,F$27,'Data Angt'!$H$5:$H$5809,$B28) -> 186 | G28: =COUNTIFS('Data Angt'!$C$5:$C$5809,G$27,'Data Angt'!$H$5:$H$5809,$B28) -> 204 | H28: =COUNTIFS('Data Angt'!$C$5:$C$5809,H$27,'Data Angt'!$H$5:$H$5809,$B28) -> 165 | I28: =COUNTIFS('Data Angt'!$C$5:$C$5809,I$27,'Data Angt'!$H$5:$H$5809,$B28) -> 114 | J28: =COUNTIFS('Data Angt'!$C$5:$C$5809,J$27,'Data Angt'!$H$5:$H$5809,$B28) -> 149 | K28: =COUNTIFS('Data Angt'!$C$5:$C$5809,K$27,'Data Angt'!$H$5:$H$5809,$B28) -> 7
B29: Karyawan | C29: =COUNTIF('Data Angt'!$H$5:$H$5809,B29) -> 1623 | D29: =C29/$C$42 -> 0.27958656 | E29: =COUNTIFS('Data Angt'!$C$5:$C$5809,E$27,'Data Angt'!$H$5:$H$5809,$B29) -> 728 | F29: =COUNTIFS('Data Angt'!$C$5:$C$5809,F$27,'Data Angt'!$H$5:$H$5809,$B29) -> 174 | G29: =COUNTIFS('Data Angt'!$C$5:$C$5809,G$27,'Data Angt'!$H$5:$H$5809,$B29) -> 264 | H29: =COUNTIFS('Data Angt'!$C$5:$C$5809,H$27,'Data Angt'!$H$5:$H$5809,$B29) -> 145 | I29: =COUNTIFS('Data Angt'!$C$5:$C$5809,I$27,'Data Angt'!$H$5:$H$5809,$B29) -> 80 | J29: =COUNTIFS('Data Angt'!$C$5:$C$5809,J$27,'Data Angt'!$H$5:$H$5809,$B29) -> 156 | K29: =COUNTIFS('Data Angt'!$C$5:$C$5809,K$27,'Data Angt'!$H$5:$H$5809,$B29) -> 76
B30: Tenaga Pengajar | C30: =COUNTIF('Data Angt'!$H$5:$H$5809,B30) -> 452 | D30: =C30/$C$42 -> 0.07786391 | E30: =COUNTIFS('Data Angt'!$C$5:$C$5809,E$27,'Data Angt'!$H$5:$H$5809,$B30) -> 177 | F30: =COUNTIFS('Data Angt'!$C$5:$C$5809,F$27,'Data Angt'!$H$5:$H$5809,$B30) -> 76 | G30: =COUNTIFS('Data Angt'!$C$5:$C$5809,G$27,'Data Angt'!$H$5:$H$5809,$B30) -> 101 | H30: =COUNTIFS('Data Angt'!$C$5:$C$5809,H$27,'Data Angt'!$H$5:$H$5809,$B30) -> 40 | I30: =COUNTIFS('Data Angt'!$C$5:$C$5809,I$27,'Data Angt'!$H$5:$H$5809,$B30) -> 29 | J30: =COUNTIFS('Data Angt'!$C$5:$C$5809,J$27,'Data Angt'!$H$5:$H$5809,$B30) -> 25 | K30: =COUNTIFS('Data Angt'!$C$5:$C$5809,K$27,'Data Angt'!$H$5:$H$5809,$B30) -> 4
B31: Aparatur/Pejabat Negara | C31: =COUNTIF('Data Angt'!$H$5:$H$5809,B31) -> 243 | D31: =C31/$C$42 -> 0.041860465 | E31: =COUNTIFS('Data Angt'!$C$5:$C$5809,E$27,'Data Angt'!$H$5:$H$5809,$B31) -> 160 | F31: =COUNTIFS('Data Angt'!$C$5:$C$5809,F$27,'Data Angt'!$H$5:$H$5809,$B31) -> 30 | G31: =COUNTIFS('Data Angt'!$C$5:$C$5809,G$27,'Data Angt'!$H$5:$H$5809,$B31) -> 16 | H31: =COUNTIFS('Data Angt'!$C$5:$C$5809,H$27,'Data Angt'!$H$5:$H$5809,$B31) -> 15 | I31: =COUNTIFS('Data Angt'!$C$5:$C$5809,I$27,'Data Angt'!$H$5:$H$5809,$B31) -> 7 | J31: =COUNTIFS('Data Angt'!$C$5:$C$5809,J$27,'Data Angt'!$H$5:$H$5809,$B31) -> 9 | K31: =COUNTIFS('Data Angt'!$C$5:$C$5809,K$27,'Data Angt'!$H$5:$H$5809,$B31) -> 6
B32: Pelajar/Mahasiswa | C32: =COUNTIF('Data Angt'!$H$5:$H$5809,B32) -> 235 | D32: =C32/$C$42 -> 0.040482343 | E32: =COUNTIFS('Data Angt'!$C$5:$C$5809,E$27,'Data Angt'!$H$5:$H$5809,$B32) -> 96 | F32: =COUNTIFS('Data Angt'!$C$5:$C$5809,F$27,'Data Angt'!$H$5:$H$5809,$B32) -> 18 | G32: =COUNTIFS('Data Angt'!$C$5:$C$5809,G$27,'Data Angt'!$H$5:$H$5809,$B32) -> 59 | H32: =COUNTIFS('Data Angt'!$C$5:$C$5809,H$27,'Data Angt'!$H$5:$H$5809,$B32) -> 14 | I32: =COUNTIFS('Data Angt'!$C$5:$C$5809,I$27,'Data Angt'!$H$5:$H$5809,$B32) -> 30 | J32: =COUNTIFS('Data Angt'!$C$5:$C$5809,J$27,'Data Angt'!$H$5:$H$5809,$B32) -> 18 | K32: =COUNTIFS('Data Angt'!$C$5:$C$5809,K$27,'Data Angt'!$H$5:$H$5809,$B32) -> 0
B33: Pemuka Agama | C33: =COUNTIF('Data Angt'!$H$5:$H$5809,B33) -> 53 | D33: =C33/$C$42 -> 0.0091300603 | E33: =COUNTIFS('Data Angt'!$C$5:$C$5809,E$27,'Data Angt'!$H$5:$H$5809,$B33) -> 33 | F33: =COUNTIFS('Data Angt'!$C$5:$C$5809,F$27,'Data Angt'!$H$5:$H$5809,$B33) -> 0 | G33: =COUNTIFS('Data Angt'!$C$5:$C$5809,G$27,'Data Angt'!$H$5:$H$5809,$B33) -> 10 | H33: =COUNTIFS('Data Angt'!$C$5:$C$5809,H$27,'Data Angt'!$H$5:$H$5809,$B33) -> 2 | I33: =COUNTIFS('Data Angt'!$C$5:$C$5809,I$27,'Data Angt'!$H$5:$H$5809,$B33) -> 1 | J33: =COUNTIFS('Data Angt'!$C$5:$C$5809,J$27,'Data Angt'!$H$5:$H$5809,$B33) -> 6 | K33: =COUNTIFS('Data Angt'!$C$5:$C$5809,K$27,'Data Angt'!$H$5:$H$5809,$B33) -> 1
B34: Mengurus Rumah Tangga | C34: =COUNTIF('Data Angt'!$H$5:$H$5809,B34) -> 848 | D34: =C34/$C$42 -> 0.14608096 | E34: =COUNTIFS('Data Angt'!$C$5:$C$5809,E$27,'Data Angt'!$H$5:$H$5809,$B34) -> 361 | F34: =COUNTIFS('Data Angt'!$C$5:$C$5809,F$27,'Data Angt'!$H$5:$H$5809,$B34) -> 71 | G34: =COUNTIFS('Data Angt'!$C$5:$C$5809,G$27,'Data Angt'!$H$5:$H$5809,$B34) -> 206 | H34: =COUNTIFS('Data Angt'!$C$5:$C$5809,H$27,'Data Angt'!$H$5:$H$5809,$B34) -> 50 | I34: =COUNTIFS('Data Angt'!$C$5:$C$5809,I$27,'Data Angt'!$H$5:$H$5809,$B34) -> 41 | J34: =COUNTIFS('Data Angt'!$C$5:$C$5809,J$27,'Data Angt'!$H$5:$H$5809,$B34) -> 66 | K34: =COUNTIFS('Data Angt'!$C$5:$C$5809,K$27,'Data Angt'!$H$5:$H$5809,$B34) -> 53
B35: Tenaga Ahli | C35: =COUNTIF('Data Angt'!$H$5:$H$5809,B35) -> 20 | D35: =C35/$C$42 -> 0.0034453058 | E35: =COUNTIFS('Data Angt'!$C$5:$C$5809,E$27,'Data Angt'!$H$5:$H$5809,$B35) -> 13 | F35: =COUNTIFS('Data Angt'!$C$5:$C$5809,F$27,'Data Angt'!$H$5:$H$5809,$B35) -> 3 | G35: =COUNTIFS('Data Angt'!$C$5:$C$5809,G$27,'Data Angt'!$H$5:$H$5809,$B35) -> 3 | H35: =COUNTIFS('Data Angt'!$C$5:$C$5809,H$27,'Data Angt'!$H$5:$H$5809,$B35) -> 1 | I35: =COUNTIFS('Data Angt'!$C$5:$C$5809,I$27,'Data Angt'!$H$5:$H$5809,$B35) -> 0 | J35: =COUNTIFS('Data Angt'!$C$5:$C$5809,J$27,'Data Angt'!$H$5:$H$5809,$B35) -> 0 | K35: =COUNTIFS('Data Angt'!$C$5:$C$5809,K$27,'Data Angt'!$H$5:$H$5809,$B35) -> 0
B36: Tenaga Medis | C36: =COUNTIF('Data Angt'!$H$5:$H$5809,B36) -> 56 | D36: =C36/$C$42 -> 0.0096468562 | E36: =COUNTIFS('Data Angt'!$C$5:$C$5809,E$27,'Data Angt'!$H$5:$H$5809,$B36) -> 20 | F36: =COUNTIFS('Data Angt'!$C$5:$C$5809,F$27,'Data Angt'!$H$5:$H$5809,$B36) -> 5 | G36: =COUNTIFS('Data Angt'!$C$5:$C$5809,G$27,'Data Angt'!$H$5:$H$5809,$B36) -> 15 | H36: =COUNTIFS('Data Angt'!$C$5:$C$5809,H$27,'Data Angt'!$H$5:$H$5809,$B36) -> 3 | I36: =COUNTIFS('Data Angt'!$C$5:$C$5809,I$27,'Data Angt'!$H$5:$H$5809,$B36) -> 7 | J36: =COUNTIFS('Data Angt'!$C$5:$C$5809,J$27,'Data Angt'!$H$5:$H$5809,$B36) -> 5 | K36: =COUNTIFS('Data Angt'!$C$5:$C$5809,K$27,'Data Angt'!$H$5:$H$5809,$B36) -> 1
B37: Petani/Pekebun/Nelayan | C37: =COUNTIF('Data Angt'!$H$5:$H$5809,B37) -> 52 | D37: =C37/$C$42 -> 0.008957795 | E37: =COUNTIFS('Data Angt'!$C$5:$C$5809,E$27,'Data Angt'!$H$5:$H$5809,$B37) -> 6 | F37: =COUNTIFS('Data Angt'!$C$5:$C$5809,F$27,'Data Angt'!$H$5:$H$5809,$B37) -> 24 | G37: =COUNTIFS('Data Angt'!$C$5:$C$5809,G$27,'Data Angt'!$H$5:$H$5809,$B37) -> 8 | H37: =COUNTIFS('Data Angt'!$C$5:$C$5809,H$27,'Data Angt'!$H$5:$H$5809,$B37) -> 4 | I37: =COUNTIFS('Data Angt'!$C$5:$C$5809,I$27,'Data Angt'!$H$5:$H$5809,$B37) -> 0 | J37: =COUNTIFS('Data Angt'!$C$5:$C$5809,J$27,'Data Angt'!$H$5:$H$5809,$B37) -> 10 | K37: =COUNTIFS('Data Angt'!$C$5:$C$5809,K$27,'Data Angt'!$H$5:$H$5809,$B37) -> 0
B38: Pensiunan | C38: =COUNTIF('Data Angt'!$H$5:$H$5809,B38) -> 224 | D38: =C38/$C$42 -> 0.038587425 | E38: =COUNTIFS('Data Angt'!$C$5:$C$5809,E$27,'Data Angt'!$H$5:$H$5809,$B38) -> 104 | F38: =COUNTIFS('Data Angt'!$C$5:$C$5809,F$27,'Data Angt'!$H$5:$H$5809,$B38) -> 28 | G38: =COUNTIFS('Data Angt'!$C$5:$C$5809,G$27,'Data Angt'!$H$5:$H$5809,$B38) -> 38 | H38: =COUNTIFS('Data Angt'!$C$5:$C$5809,H$27,'Data Angt'!$H$5:$H$5809,$B38) -> 19 | I38: =COUNTIFS('Data Angt'!$C$5:$C$5809,I$27,'Data Angt'!$H$5:$H$5809,$B38) -> 17 | J38: =COUNTIFS('Data Angt'!$C$5:$C$5809,J$27,'Data Angt'!$H$5:$H$5809,$B38) -> 18 | K38: =COUNTIFS('Data Angt'!$C$5:$C$5809,K$27,'Data Angt'!$H$5:$H$5809,$B38) -> 0
B39: Belum/Tidak Bekerja | C39: =COUNTIF('Data Angt'!$H$5:$H$5809,B39) -> 86 | D39: =C39/$C$42 -> 0.014814815 | E39: =COUNTIFS('Data Angt'!$C$5:$C$5809,E$27,'Data Angt'!$H$5:$H$5809,$B39) -> 33 | F39: =COUNTIFS('Data Angt'!$C$5:$C$5809,F$27,'Data Angt'!$H$5:$H$5809,$B39) -> 11 | G39: =COUNTIFS('Data Angt'!$C$5:$C$5809,G$27,'Data Angt'!$H$5:$H$5809,$B39) -> 3 | H39: =COUNTIFS('Data Angt'!$C$5:$C$5809,H$27,'Data Angt'!$H$5:$H$5809,$B39) -> 8 | I39: =COUNTIFS('Data Angt'!$C$5:$C$5809,I$27,'Data Angt'!$H$5:$H$5809,$B39) -> 17 | J39: =COUNTIFS('Data Angt'!$C$5:$C$5809,J$27,'Data Angt'!$H$5:$H$5809,$B39) -> 14 | K39: =COUNTIFS('Data Angt'!$C$5:$C$5809,K$27,'Data Angt'!$H$5:$H$5809,$B39) -> 0
B40: Lain-lain | C40: =COUNTIF('Data Angt'!$H$5:$H$5809,B40) -> 246 | D40: =C40/$C$42 -> 0.042377261 | E40: =COUNTIFS('Data Angt'!$C$5:$C$5809,E$27,'Data Angt'!$H$5:$H$5809,$B40) -> 146 | F40: =COUNTIFS('Data Angt'!$C$5:$C$5809,F$27,'Data Angt'!$H$5:$H$5809,$B40) -> 22 | G40: =COUNTIFS('Data Angt'!$C$5:$C$5809,G$27,'Data Angt'!$H$5:$H$5809,$B40) -> 16 | H40: =COUNTIFS('Data Angt'!$C$5:$C$5809,H$27,'Data Angt'!$H$5:$H$5809,$B40) -> 13 | I40: =COUNTIFS('Data Angt'!$C$5:$C$5809,I$27,'Data Angt'!$H$5:$H$5809,$B40) -> 12 | J40: =COUNTIFS('Data Angt'!$C$5:$C$5809,J$27,'Data Angt'!$H$5:$H$5809,$B40) -> 37 | K40: =COUNTIFS('Data Angt'!$C$5:$C$5809,K$27,'Data Angt'!$H$5:$H$5809,$B40) -> 0
B41: Kosong | C41: =COUNTIF('Data Angt'!$H$5:$H$5809,"") -> 298 | D41: =C41/$C$42 -> 0.051335056 | E41: =COUNTIFS('Data Angt'!$C$5:$C$5809,E$27,'Data Angt'!$H$5:$H$5809,"") -> 195 | F41: =COUNTIFS('Data Angt'!$C$5:$C$5809,F$27,'Data Angt'!$H$5:$H$5809,"") -> 49 | G41: =COUNTIFS('Data Angt'!$C$5:$C$5809,G$27,'Data Angt'!$H$5:$H$5809,"") -> 1 | H41: =COUNTIFS('Data Angt'!$C$5:$C$5809,H$27,'Data Angt'!$H$5:$H$5809,"") -> 1 | I41: =COUNTIFS('Data Angt'!$C$5:$C$5809,I$27,'Data Angt'!$H$5:$H$5809,"") -> 1 | J41: =COUNTIFS('Data Angt'!$C$5:$C$5809,J$27,'Data Angt'!$H$5:$H$5809,"") -> 9 | K41: =COUNTIFS('Data Angt'!$C$5:$C$5809,K$27,'Data Angt'!$H$5:$H$5809,"") -> 42
B42: JUMLAH | C42: =SUM(C28:C41) -> 5805 | D42: =C42/$C$42 -> 1 | E42: =SUM(E28:E41) -> 2616 | F42: =SUM(F28:F41) -> 697 | G42: =SUM(G28:G41) -> 944 | H42: =SUM(H28:H41) -> 480 | I42: =SUM(I28:I41) -> 356 | J42: =SUM(J28:J41) -> 522 | K42: =SUM(K28:K41) -> 190
A44: 3 | B44: KLASIFIKASI PROFESI DAN USIA ANGGOTA
B46: Usia | C46: Profesi | D46: Jumlah | E46: % | F46: PBL | G46: KRK | H46: JBR | I46: BWI | J46: MJK | K46: MGL | L46: PML
B47: <24 Th | C47: Wiraswasta | D47: =COUNTIFS('Data Angt'!$F$5:$F$5809,"<24",'Data Angt'!$H$5:$H$5809,C47) -> 18 | E47: =D47/$C$42 -> 0.0031007752 | F47: =COUNTIFS('Data Angt'!$C$5:$C$5809,F$46,'Data Angt'!$F$5:$F$5809,"<24",'Data Angt'!$H$5:$H$5809,$C47) -> 3 | G47: =COUNTIFS('Data Angt'!$C$5:$C$5809,G$46,'Data Angt'!$F$5:$F$5809,"<24",'Data Angt'!$H$5:$H$5809,$C47) -> 2 | H47: =COUNTIFS('Data Angt'!$C$5:$C$5809,H$46,'Data Angt'!$F$5:$F$5809,"<24",'Data Angt'!$H$5:$H$5809,$C47) -> 3 | I47: =COUNTIFS('Data Angt'!$C$5:$C$5809,I$46,'Data Angt'!$F$5:$F$5809,"<24",'Data Angt'!$H$5:$H$5809,$C47) -> 8 | J47: =COUNTIFS('Data Angt'!$C$5:$C$5809,J$46,'Data Angt'!$F$5:$F$5809,"<24",'Data Angt'!$H$5:$H$5809,$C47) -> 0 | K47: =COUNTIFS('Data Angt'!$C$5:$C$5809,K$46,'Data Angt'!$F$5:$F$5809,"<24",'Data Angt'!$H$5:$H$5809,$C47) -> 2 | L47: =COUNTIFS('Data Angt'!$C$5:$C$5809,L$46,'Data Angt'!$F$5:$F$5809,"<24",'Data Angt'!$H$5:$H$5809,$C47) -> 0
C48: Karyawan | D48: =COUNTIFS('Data Angt'!$F$5:$F$5809,"<24",'Data Angt'!$H$5:$H$5809,C48) -> 81 | E48: =D48/$C$42 -> 0.013953488 | F48: =COUNTIFS('Data Angt'!$C$5:$C$5809,F$46,'Data Angt'!$F$5:$F$5809,"<24",'Data Angt'!$H$5:$H$5809,$C48) -> 57 | G48: =COUNTIFS('Data Angt'!$C$5:$C$5809,G$46,'Data Angt'!$F$5:$F$5809,"<24",'Data Angt'!$H$5:$H$5809,$C48) -> 3 | H48: =COUNTIFS('Data Angt'!$C$5:$C$5809,H$46,'Data Angt'!$F$5:$F$5809,"<24",'Data Angt'!$H$5:$H$5809,$C48) -> 2 | I48: =COUNTIFS('Data Angt'!$C$5:$C$5809,I$46,'Data Angt'!$F$5:$F$5809,"<24",'Data Angt'!$H$5:$H$5809,$C48) -> 11 | J48: =COUNTIFS('Data Angt'!$C$5:$C$5809,J$46,'Data Angt'!$F$5:$F$5809,"<24",'Data Angt'!$H$5:$H$5809,$C48) -> 4 | K48: =COUNTIFS('Data Angt'!$C$5:$C$5809,K$46,'Data Angt'!$F$5:$F$5809,"<24",'Data Angt'!$H$5:$H$5809,$C48) -> 4 | L48: =COUNTIFS('Data Angt'!$C$5:$C$5809,L$46,'Data Angt'!$F$5:$F$5809,"<24",'Data Angt'!$H$5:$H$5809,$C48) -> 0
...

Sheet Pinjaman
A1: Laporan Saldo Pinjaman Anggota
A3: Semua Produk Pinjaman
A4: Semua TP
